Workbook

Sheet UnbundleCosting
A1: Thaba Chweu Municipality Mast Lights Project | D1: Project Code | G1: ___________________________________________________
A3: Financial System Spend | D3: =Finance_Invoices!G11 -> 3617976.3 | H3: Financial Spending | K3: =K5*K4 -> 566801.01 | L3: =L5*L4 -> 2531711.2 | M3: =M5*M4 -> 1037623.7 | N3: =SUM(K3:M3) -> 4136135.9 | O3: =D3-N3 -> -518159.62
A4: Bill of Quantities | D4: =G31 -> 3868390 | H4: Actual Unit Cost | K4: =K35/K5*$D$5 -> 28340.05 | L4: =L35/L5*$D$5 -> 126585.56 | M4: =M35/M5*$D$5 -> 51881.186
A5: Ratio | D5: =D4/D3 -> 1.0692138 | H5: Actual Survey | K5: ='Values FAR'!H66 -> 20 | L5: ='Values FAR'!H22 -> 20 | M5: ='Values FAR'!H44 -> 20
H6: BoQ | K6: 20 | L6: 20 | M6: 20
H7: Unit | K7: ea | L7: ea | M7: ea
A9: ITEM NO | B9: PAYMENT REFERS | C9: ITEM DESCRIPTION | D9: AMOUNT TENDERED | I9: P & G | J9: General | K9: High Mast Light
D10: UNIT | E10: QUANTITY | F10: RATE | G10: AMOUNT | K10: Plynth | L10: Mast | M10: Light
A11: Schedule 1
A12: PRELIMINARY & GENERAL
B13: 1 | C13: Preliminary & General | D13: PC SUM | E13: 0 | G13: 301400 | I13: =G13 -> 301400 | O13: =G13-SUM(I13:M13) -> 0
C14: Retention | G14: 184209.05 | I14: =G14 -> 184209.05 | O14: =G14-SUM(I14:M14) -> 0
C15: Supply, Installation, testing and commissioning of Mast Structures | O15: =G15-SUM(I15:M15) -> 0
B16: 1 | C16: Supply of 3-rope hoisting Highlight mast with brackets and foundation bolts ex works | D16: EA | E16: 20 | F16: 30373.348 | G16: 607466.96 | L16: =G16 -> 607466.96 | O16: =G16-SUM(I16:M16) -> 0
B17: 2 | C17: Mast internal glass fibre IP30 Db with photo cell, IP65 Splitterbox and 5core x 2,5mm training cable (No surge protection) | D17: EA | E17: 20 | F17: 3239.8238 | G17: 64796.476 | J17: =G17 -> 64796.476 | O17: =G17-SUM(I17:M17) -> 0
B18: 3 | C18: Concrete foundation complete with soil and concrete cube tests | D18: EA | E18: 20 | F18: 15186.674 | G18: 303733.48 | K18: =G18 -> 303733.48 | O18: =G18-SUM(I18:M18) -> 0
B19: 4 | C19: Earthing: Supply and Install Sectionalpoles standard system consisting of 2x2.1m earth spikes complete with 2 x 70 mm² copper conductor wih 2x brass clamps | D19: EA | E19: 20 | F19: 30373.348 | G19: 607466.96 | L19: =G19 -> 607466.96 | O19: =G19-SUM(I19:M19) -> 0
B20: 5 | C20: Delivery of masts to site (Per Load) | D20: EA | E20: 4 | F20: 15186.674 | G20: 60746.696 | L20: =G20 -> 60746.696 | O20: =G20-SUM(I20:M20) -> 0
B21: 6 | C21: Assemble and erection of mast (By supplier to ensure mast Guarantee) | D21: EA | E21: 8 | F21: 10124.449 | G21: 80995.594 | L21: =G21 -> 80995.594 | O21: =G21-SUM(I21:M21) -> 0
B22: 7 | C22: Luminaires complete with lamp | D22: EA | E22: 180 | F22: 2925.9658 | G22: 526673.85 | M22: =G22 -> 526673.85 | O22: =G22-SUM(I22:M22) -> 0
B23: 8 | C23: Mounting and wiring of luminaires per mast (assuming light fittingd are on site abd aiming angles provided before hand) | D23: EA | E23: 20 | F23: 1468.0451 | G23: 29360.903 | M23: =G23 -> 29360.903 | O23: =G23-SUM(I23:M23) -> 0
B24: 9 | C24: Electrical Connections | D24: sum | E24: 1 | F24: 809955.94 | G24: 809955.94 | J24: =G24 -> 809955.94 | O24: =G24-SUM(I24:M24) -> 0
G25: 0 | O25: =G25-SUM(I25:M25) -> 0
C26: Servicing Equipment (1 set per site is recommended) | G26: 0 | O26: =G26-SUM(I26:M26) -> 0
B27: 9 | C27: Single drum which complete with stainless steel rope and winch | D27: EA | E27: 1 | F27: 32398.238 | G27: 32398.238 | J27: =G27 -> 32398.238 | O27: =G27-SUM(I27:M27) -> 0
B28: 10 | C28: Hydrualic powertool with remote control | D28: EA | E28: 1 | F28: 6074.6696 | G28: 6074.6696 | J28: =G28 -> 6074.6696 | O28: =G28-SUM(I28:M28) -> 0
B29: 11 | C29: Test lead - in order to test operation of lights if mast is lowered | D29: EA | E29: 1 | F29: 101244.49 | G29: 101244.49 | J29: =G29 -> 101244.49 | O29: =G29-SUM(I29:M29) -> 0
B30: 12 | C30: Negotiations and application to supply authorities | D30: sum | E30: 1 | F30: 151866.74 | G30: 151866.74 | J30: =G30 -> 151866.74 | O30: =G30-SUM(I30:M30) -> 0
G31: =SUM(G13:G30) -> 3868390 | I31: =SUM(I13:I30) -> 485609.05 | J31: =SUM(J13:J30) -> 1166336.6 | K31: =SUM(K13:K30) -> 303733.48 | L31: =SUM(L13:L30) -> 1356676.2 | M31: =SUM(M13:M30) -> 556034.76 | N31: =SUM(I31:M31) -> 3868390.1 | O31: =G31-N31 -> 0
H32: Distribute General Values | J32: =-J31 -> -1166336.6 | K32: =K31/($K$31+$L$31+$M$31)*$J$31 -> 159830.52 | L32: =L31/($K$31+$L$31+$M$31)*$J$31 -> 713909.64 | M32: =M31/($K$31+$L$31+$M$31)*$J$31 -> 292596.4 | N32: =SUM(J32:M32) -> 0
I33: =I31+I32 -> 485609.05 | J33: =J31+J32 -> 0 | K33: =K31+K32 -> 463564 | L33: =L31+L32 -> 2070585.8 | M33: =M31+M32 -> 848631.16 | N33: =SUM(I33:M33) -> 3868390
H34: Distribute P & G | I34: =-I33 -> -485609.05 | K34: =K33/($K$33+$L$33+$M$33)*$I$33 -> 66546.097 | L34: =L33/($K$33+$L$33+$M$33)*$I$33 -> 297239.23 | M34: =M33/($K$33+$L$33+$M$33)*$I$33 -> 121823.72 | N34: =SUM(I34:M34) -> 0
I35: =I33+I34 -> 0 | J35: =J33+J34 -> 0 | K35: =K33+K34 -> 530110.09 | L35: =L33+L34 -> 2367825.1 | M35: =M33+M34 -> 970454.88 | N35: =SUM(I35:M35) -> 3868390
H36: Unit Cost on BoQ | K36: =K35/K6 -> 26505.505 | L36: =L35/L6 -> 118391.25 | M36: =M35/M6 -> 48522.744

Sheet Finance_Invoices
A1: Period | B1: Votenumber | C1: Vote Description | D1: Transaction Type | E1: Reference | F1: TranDate | G1: Debit Amt | H1: Credit Amt | I1: Transaction Description | J1: Originating Description | K1: Bnk | L1: Cheque | M1: Cheque Amt | N1: Status | O1: Payee
A2: 201711 | C2: PLANT AND EQUIPMENT(HIGH MAST LIGHT ) | D2: Sundry Payments | F2: 20141107 | G2: 1188522 | H2: 0 | I2: RJJ PROJECT MANAGEMENT (PTY)LTD | J2: Cheque No : 16459 Bank No : 777 | K2: 777 | L2: 16459 | M2: 1354915.1 | N2: Cashed | O2: RJJ PROJECT MANAGEMENT (PTY)LTD
A3: 201711 | C3: PLANT AND EQUIPMENT(HIGH MAST LIGHT ) | D3: Sundry Payments | F3: 20141203 | G3: 118554.69 | H3: 0 | I3: INGPLAN CONSULTING ENGINEERS (PTY)LTD | J3: Cheque No : 16682 Bank No : 777 | K3: 777 | L3: 16682 | M3: 135152.35 | N3: Cashed | O3: INGPLAN CONSULTING ENGINEERS (PTY)LTD
A4: 201711 | C4: PLANT AND EQUIPMENT(HIGH MAST LIGHT ) | D4: Sundry Payments | F4: 20141203 | G4: 809456.95 | H4: 0 | I4: RJJ PROJECT MANAGEMENT (PTY)LTD | J4: Cheque No : 16685 Bank No : 777 | K4: 777 | L4: 16685 | M4: 922780.92 | N4: Cashed | O4: RJJ PROJECT MANAGEMENT (PTY)LTD
A5: 201802 | C5: PLANT AND EQUIPMENT(HIGH MAST LIGHT ) | D5: Sundry Payments | F5: 20150225 | G5: 902983 | H5: 0 | I5: RJJ PROJECT MANAGEMENT (PTY)LTD | J5: Cheque No : 17367 Bank No : 777 | K5: 777 | L5: 17367 | M5: 1029400.6 | N5: Cashed | O5: RJJ PROJECT MANAGEMENT (PTY)LTD
A6: 201802 | C6: PLANT AND EQUIPMENT(HIGH MAST LIGHT ) | D6: Ledger Journals | E6: 153 | F6: 20150513 | G6: 74068.21 | H6: 0 | I6: CORRECTION OF EXPENDITURE TO CORRECTED VOTES | J6: CORRECTION OF EXPENDITURE TO CORRECTED VOTES
A7: 201802 | C7: PLANT AND EQUIPMENT(HIGH MAST LIGHT ) | D7: Ledger Journals | E7: 153 | F7: 20150513 | G7: 365255 | H7: 0 | I7: CORRECTION OF EXPENDITURE TO CORRECTED VOTES | J7: CORRECTION OF EXPENDITURE TO CORRECTED VOTES
A8: 201802 | C8: PLANT AND EQUIPMENT(HIGH MAST LIGHT ) | D8: Ledger Journals | E8: 153 | F8: 20150513 | G8: 70220.4 | H8: 0 | I8: CORRECTION OF EXPENDITURE TO CORRECTED VOTES | J8: CORRECTION OF EXPENDITURE TO CORRECTED VOTES
A9: 201802 | C9: PLANT AND EQUIPMENT(HIGH MAST LIGHT ) | D9: Ledger Journals | E9: 153 | F9: 20150513 | G9: 88916.03 | H9: 0 | I9: CORRECTION OF EXPENDITURE TO CORRECTED VOTES | J9: CORRECTION OF EXPENDITURE TO CORRECTED VOTES
G11: =G2+G3+G4+G5+G6+G7+G8+G9 -> 3617976.3 | M11: =SUM(M2:M10) -> 3442249

Sheet Values FAR
A1: ComponentId | B1: Asset | C1: Component | D1: EUL | E1: Financial_Status | F1: Description | G1: Project_Name | H1: length_qty | I1: width | J1: area | K1: AQC
A2: 793230441 | B2: High Mast | C2: High Mast | E2: ADD | F2: 30 m Steel High Mast | G2: Lekwa Teemane High Mast Lights Phase 2 | H2: 1 | K2: =H2*UnbundleCosting!$L$4 -> 126585.56
A3: 793309441 | B3: High Mast | C3: High Mast | E3: ADD | F3: 30 m Steel High Mast | G3: Lekwa Teemane High Mast Lights Phase 2 | H3: 1 | K3: =H3*UnbundleCosting!$L$4 -> 126585.56
A4: 793469441 | B4: High Mast | C4: High Mast | E4: ADD | F4: 30 m Steel High Mast | G4: Lekwa Teemane High Mast Lights Phase 2 | H4: 1 | K4: =H4*UnbundleCosting!$L$4 -> 126585.56
A5: 793506441 | B5: High Mast | C5: High Mast | E5: ADD | F5: 30 m Steel High Mast | G5: Lekwa Teemane High Mast Lights Phase 2 | H5: 1 | K5: =H5*UnbundleCosting!$L$4 -> 126585.56
A6: 793810462 | B6: High Mast | C6: High Mast | E6: ADD | F6: 30 m Steel High Mast | G6: Lekwa Teemane High Mast Lights Phase 2 | H6: 1 | K6: =H6*UnbundleCosting!$L$4 -> 126585.56
A7: 793843462 | B7: High Mast | C7: High Mast | E7: ADD | F7: 30 m Steel High Mast | G7: Lekwa Teemane High Mast Lights Phase 2 | H7: 1 | K7: =H7*UnbundleCosting!$L$4 -> 126585.56
A8: 793847441 | B8: High Mast | C8: High Mast | E8: ADD | F8: 30 m Steel High Mast | G8: Lekwa Teemane High Mast Lights Phase 2 | H8: 1 | K8: =H8*UnbundleCosting!$L$4 -> 126585.56
A9: 793924462 | B9: High Mast | C9: High Mast | E9: ADD | F9: 30 m Steel High Mast | G9: Lekwa Teemane High Mast Lights Phase 2 | H9: 1 | K9: =H9*UnbundleCosting!$L$4 -> 126585.56
A10: 793959462 | B10: High Mast | C10: High Mast | E10: ADD | F10: 30 m Steel High Mast | G10: Lekwa Teemane High Mast Lights Phase 2 | H10: 1 | K10: =H10*UnbundleCosting!$L$4 -> 126585.56
A11: 794006462 | B11: High Mast | C11: High Mast | E11: ADD | F11: 30 m Steel High Mast | G11: Lekwa Teemane High Mast Lights Phase 2 | H11: 1 | K11: =H11*UnbundleCosting!$L$4 -> 126585.56
A12: 794736441 | B12: High Mast | C12: High Mast | E12: ADD | F12: 30 m Steel High Mast | G12: Lekwa Teemane High Mast Lights Phase 2 | H12: 1 | K12: =H12*UnbundleCosting!$L$4 -> 126585.56
A13: 803095460 | B13: High Mast | C13: High Mast | E13: ADD | F13: 30 m Steel High Mast | G13: Lekwa Teemane High Mast Lights Phase 2 | H13: 1 | K13: =H13*UnbundleCosting!$L$4 -> 126585.56
... A21: 803553462 | B21: High Mast | C21: High Mast | E21: ADD | F21: 30 m Steel High Mast | G21: Lekwa Teemane High Mast Lights Phase 2 | H21: 1 | K21: =H21*UnbundleCosting!$L$4 -> 126585.56
H22: =SUM(H2:H21) -> 20 | K22: =SUM(K2:K21) -> 2531711.2 | L22: =K22-UnbundleCosting!L3 -> 0
A24: 793252441 | B24: High Mast | C24: High Mast Light | E24: ADD | F24: 9 Lights | G24: Lekwa Teemane High Mast Lights Phase 2 | H24: 1 | K24: =H24*UnbundleCosting!$M$4 -> 51881.186
A25: 793316441 | B25: High Mast | C25: High Mast Light | E25: ADD | F25: 9 Lights | G25: Lekwa Teemane High Mast Lights Phase 2 | H25: 1 | K25: =H25*UnbundleCosting!$M$4 -> 51881.186
A26: 793478441 | B26: High Mast | C26: High Mast Light | E26: ADD | F26: 9 Lights | G26: Lekwa Teemane High Mast Lights Phase 2 | H26: 1 | K26: =H26*UnbundleCosting!$M$4 -> 51881.186
A27: 793524441 | B27: High Mast | C27: High Mast Light | E27: ADD | F27: 9 Lights | G27: Lekwa Teemane High Mast Lights Phase 2 | H27: 1 | K27: =H27*UnbundleCosting!$M$4 -> 51881.186
A28: 793817462 | B28: High Mast | C28: High Mast Light | E28: ADD | F28: 9 Lights | G28: Lekwa Teemane High Mast Lights Phase 2 | H28: 1 | K28: =H28*UnbundleCosting!$M$4 -> 51881.186
A29: 793859462 | B29: High Mast | C29: High Mast Light | E29: ADD | F29: 9 Lights | G29: Lekwa Teemane High Mast Lights Phase 2 | H29: 1 | K29: =H29*UnbundleCosting!$M$4 -> 51881.186
A30: 793867441 | B30: High Mast | C30: High Mast Light | E30: ADD | F30: 9 Lights | G30: Lekwa Teemane High Mast Lights Phase 2 | H30: 1 | K30: =H30*UnbundleCosting!$M$4 -> 51881.186
A31: 793942462 | B31: High Mast | C31: High Mast Light | E31: ADD | F31: 9 Lights | G31: Lekwa Teemane High Mast Lights Phase 2 | H31: 1 | K31: =H31*UnbundleCosting!$M$4 -> 51881.186
A32: 793975462 | B32: High Mast | C32: High Mast Light | E32: ADD | F32: 9 Lights | G32: Lekwa Teemane High Mast Lights Phase 2 | H32: 1 | K32: =H32*UnbundleCosting!$M$4 -> 51881.186
A33: 794022462 | B33: High Mast | C33: High Mast Light | E33: ADD | F33: 9 Lights | G33: Lekwa Teemane High Mast Lights Phase 2 | H33: 1 | K33: =H33*UnbundleCosting!$M$4 -> 51881.186
A34: 794754441 | B34: High Mast | C34: High Mast Light | E34: ADD | F34: 9 Lights | G34: Lekwa Teemane High Mast Lights Phase 2 | H34: 1 | K34: =H34*UnbundleCosting!$M$4 -> 51881.186
A35: 803114460 | B35: High Mast | C35: High Mast Light | E35: ADD | F35: 9 Lights | G35: Lekwa Teemane High Mast Lights Phase 2 | H35: 1 | K35: =H35*UnbundleCosting!$M$4 -> 51881.186
... A43: 803559462 | B43: High Mast | C43: High Mast Light | E43: ADD | F43: 9 Lights | G43: Lekwa Teemane High Mast Lights Phase 2 | H43: 1 | K43: =H43*UnbundleCosting!$M$4 -> 51881.186
H44: =SUM(H24:H43) -> 20 | K44: =SUM(K24:K43) -> 1037623.7 | L44: =K44-UnbundleCosting!M3 -> 0
A46: 793243441 | B46: High Mast | C46: Plynth | E46: ADD | F46: Concrete Plynth for High Mast | G46: Lekwa Teemane High Mast Lights Phase 2 | H46: 1 | K46: =H46*UnbundleCosting!$K$4 -> 28340.05
A47: 793333441 | B47: High Mast | C47: Plynth | E47: ADD | F47: Concrete Plynth for High Mast | G47: Lekwa Teemane High Mast Lights Phase 2 | H47: 1 | K47: =H47*UnbundleCosting!$K$4 -> 28340.05
A48: 793491441 | B48: High Mast | C48: Plynth | E48: ADD | F48: Concrete Plynth for High Mast | G48: Lekwa Teemane High Mast Lights Phase 2 | H48: 1 | K48: =H48*UnbundleCosting!$K$4 -> 28340.05
A49: 793515441 | B49: High Mast | C49: Plynth | E49: ADD | F49: Concrete Plynth for High Mast | G49: Lekwa Teemane High Mast Lights Phase 2 | H49: 1 | K49: =H49*UnbundleCosting!$K$4 -> 28340.05
A50: 793830462 | B50: High Mast | C50: Plynth | E50: ADD | F50: Concrete Plynth for High Mast | G50: Lekwa Teemane High Mast Lights Phase 2 | H50: 1 | K50: =H50*UnbundleCosting!$K$4 -> 28340.05
A51: 793850462 | B51: High Mast | C51: Plynth | E51: ADD | F51: Concrete Plynth for High Mast | G51: Lekwa Teemane High Mast Lights Phase 2 | H51: 1 | K51: =H51*UnbundleCosting!$K$4 -> 28340.05
A52: 793858441 | B52: High Mast | C52: Plynth | E52: ADD | F52: Concrete Plynth for High Mast | G52: Lekwa Teemane High Mast Lights Phase 2 | H52: 1 | K52: =H52*UnbundleCosting!$K$4 -> 28340.05
A53: 793933462 | B53: High Mast | C53: Plynth | E53: ADD | F53: Concrete Plynth for High Mast | G53: Lekwa Teemane High Mast Lights Phase 2 | H53: 1 | K53: =H53*UnbundleCosting!$K$4 -> 28340.05
A54: 793966462 | B54: High Mast | C54: Plynth | E54: ADD | F54: Concrete Plynth for High Mast | G54: Lekwa Teemane High Mast Lights Phase 2 | H54: 1 | K54: =H54*UnbundleCosting!$K$4 -> 28340.05
A55: 794013462 | B55: High Mast | C55: Plynth | E55: ADD | F55: Concrete Plynth for High Mast | G55: Lekwa Teemane High Mast Lights Phase 2 | H55: 1 | K55: =H55*UnbundleCosting!$K$4 -> 28340.05
A56: 794745441 | B56: High Mast | C56: Plynth | E56: ADD | F56: Concrete Plynth for High Mast | G56: Lekwa Teemane High Mast Lights Phase 2 | H56: 1 | K56: =H56*UnbundleCosting!$K$4 -> 28340.05
...
