Workbook

Sheet FAR
A1: Scenario | D1: FinancialYear | E1: FinancialPeriod | F1: AssetRegisterItemID | G1: MunicipalAssetID | H1: ParentAssetRegisterItem_ID | I1: MainAssetDescription | J1: MainAssetID | K1: AssetDescription | L1: OldBarcode | M1: Barcode | N1: ImageRef | O1: AssetType | P1: AssetCategory | Q1: AssetSubCategory | R1: AssetClass | S1: MeasurementType_ID2 | T1: AssetStatus | U1: CIDMSSubComponentType | V1: CIDMSComponentType | W1: CIDMSAccountingGroup | X1: CIDMSSubAccountingGroup | Y1: CIDMSAssetClass | Z1: CIDMSAssetGroupType | AA1: CIDMSAssetType | AB1: NatureOfAddition | AC1: InfrastructurOrNonInfrastructure | AD1: CashNonCashGeneratingUnit | AE1: FinancialStatus | AF1: TakeOnDate | AG1: AquisitionDate | AH1: System_In_Service_Date | AI1: DisposalDate | AJ1: DisposalReason | AK1: Impairment_Date | AL1: DateModified | AM1: VerificationDate | AN1: VerificationDoneBy | AO1: YearConstructed | AP1: CommisioningDate | AQ1: ConstructionMaterial | AR1: ForecastReplacementYear | AS1: AssetCondition | AT1: InsuranceCover | AU1: InsurancePolicy | AV1: Warranty | AW1: CurrentReplacementCostCRC | AX1: DepreciatedReplacementCostDRC | AY1: AnnualisedMaintenanceCRC | AZ1: AnnualMaintenanceBudgetNeed | BA1: DepreciationMethod | BB1: UsefulLifeYearComponent | BC1: UsefulLifeMonthComponent | BD1: UsefulLifeDaysComponent | BE1: Remaining_Useful_Life_Year | BF1: Remaining_Useful_Life_Months | BG1: Remaining_Useful_Life_Days | BH1: RemainingUsefulllifeAtTakeon | BI1: UOM | BJ1: Dim1 | BK1: Dim2 | BL1: Dim3 | BM1: DimensionQuantity | BN1: Quantity | BO1: Diameter | BP1: Capacity | BQ1: SGNumberChange_ID | BR1: DeedNumber | BS1: ErfNumber | BT1: ErfSizeM2 | BU1: PortionNumber | BV1: UnitNumber | BW1: RegistrationNumber | BX1: SerialNumber | BY1: CustodianName | BZ1: CustodianIdNumber | CA1: BasicMunicipalServices | CB1: CriticalityGrade | CC1: PerformanceGrade | CD1: UtilisationGrade | CE1: InfrastructureHealthGrade | CF1: ConsequenceOfFailure | CG1: Risk | CH1: AssetOwnership | CI1: Department | CJ1: Division | CK1: Town | CL1: StreetName | CM1: Building | CN1: Ward | CO1: Zoning | CP1: FloorArea | CQ1: RoomNumber | CR1: Suburb | CS1: WellKnownTextWKT | CT1: GISID | CU1: Latitude | CV1: Longitude | CW1: FundingSourceAmount | CX1: FundingSourceNumber | CY1: FundType | CZ1: CostOfAddition | DA1: Revaluation_Date | DB1: Revaluation_Value | DC1: Accumulated_Revalutions_Opening_Balance | DD1: Revaluation_Reserve_Impairments_OpeningBalance | DE1: Revaluation_Reserve_Impairments | DF1: Revaluation_Reserve_Impairment_Reversals | DG1: Revaluation_Reserve_Impairments_ClosingBalance | DH1: Revaluation_Reserve_Revaluations | DI1: Revaluation_Reserve_Disposals | DJ1: Refurb_Revaluation | DK1: Accumulated_Revaluation_Closing_Balance | DL1: Movement_In_Revaluation_Reserve | DM1: DepreciationOffsetOpeningBalance | DN1: DepreciationOffset | DO1: DepreciationOffsetClosingBalance | DP1: Revaluation_Surplus_Deficit | DQ1: Deemed_Cost | DR1: Cost_OpeningBalance | DS1: Cost_RestatedOpeningBalance | DT1: Cost_Acquisitions | DU1: Cost_RisidualValue | DV1: WorkInProgress | DW1: TransferFromAmount | DX1: TransferToAmount | DY1: RefurbishmentCredit | DZ1: RefurbishmentDebit | EA1: Cost_FairValueAdjustment | EB1: Revaluation_Adjustment | EC1: Cost_Disposal | ED1: Cost_ClosingBalance | EE1: AccumulatedDepreciation_OpeningBalance | EF1: AccumulatedDepreciation_RestatedOpeningBalance | EG1: AccumulatedDepreciation_Depreciation | EH1: DepreciationAdjustments | EI1: AccumulatedDepreciation_Disposal | EJ1: Refurb_Depreciation | EK1: AccumulatedDepreciation_ClosingBalance | EL1: AccumulatedImpairment_OpeningBalance | EM1: AccumulatedImpairment_RestatedOpeningBalance | EN1: AccumulatedImpairmentImpairment | EO1: AccumulatedImpairment_ReversalOfImpairment | EP1: AccumulatedImpairment_Disposal | EQ1: AccumulatedImpairment_ClosingBalance | ER1: CarryingAmount | ES1: Disposal_Proceeds | ET1: Disposal_Profit_Loss | EU1: DonorIDRegistrationNumberParastatalCode | EV1: DonorNameCompanyRegistrationNumberParastatalName | EW1: Date_Donated | EX1: Make | EY1: Model | EZ1: Custom_1 | FA1: Custom_2 | FB1: Custom_3 | FC1: Custom_4 | FD1: Custom_5 | FE1: Custom_6 | FF1: Custom_7 | FG1: Custom_8 | FH1: Custom_9
A4: 1.1 - Cost increase due to incorrect t treatment of WIP, Retentions, VAT, etc. Cost increases from R3,046,098.51 to R3,807,623.14 | C4: Original values captured | D4: 2025/2026 | E4: 0 | F4: 10767 | G4: RD07909/000 | H4: RD07909 | I4: Unpaved Road | K4: Unpaved Road | O4: Property, Plant and Equipment | P4: Roads Infrastructure | Q4: Roads | R4: Unpaved Road | S4: Revaluation Module | U4: Unpaved Road | V4: Unpaved Road | W4: Property, plant and equipment | X4: Infrastructure assets | Y4: Roads infrastructure | Z4: Roads | AA4: Pavements | AB4: New | AC4: Infrastructure | AD4: Non Cash | AE4: EAR (Existing Asset Register) | AF4: 45306 | AG4: 45306 | AH4: 45306 | AL4: 45306 | AM4: 45473 | AN4: Lundi Knox Nxawe | AP4: 45473 | AS4: Good | AT4: No | AV4: No | AW4: 3046098.5 | AX4: =ER4 -> 2601284.8 | AY4: 0 | AZ4: 0 | BA4: Straight-line | BB4: 10 | BC4: 120 | BD4: 3650 | BE4: =BG4/365 -> 8.539726 | BF4: =BE4*12 -> 102.47671 | BG4: ='1'!$B$28 -> 3117 | BI4: Square Meter | BN4: 1 | BO4: 0 | BP4: 0 | BY4: Zanele Nontando Mbusi | BZ4: 830910xxxxxxx | CA4: Yes | CB4: Important | CC4: Meets requirements | CD4: Normal use | CE4: Very good | CF4: Moderate | CG4: Medium | CH4: Mnquma Local Municipality | CI4: Infrastructural Planning & Development | CJ4: Civil Services | CK4: Butterworth | CN4: Ward 1 | CU4: -32.188584 | CV4: 28.055332 | CW4: =DS4 -> 3046098.5 | CX4: 0 | DA4: 1 | DB4: 3036924.8 | DC4: 0 | DD4: 0 | DE4: 0 | DF4: 0 | DG4: 0 | DH4: 0 | DI4: 0 | DJ4: 0 | DK4: 0 | DL4: 0 | DM4: 0 | DN4: 0 | DO4: 0 | DP4: 0 | DQ4: Yes | DR4: ='1'!$B$5 -> 3046098.5 | DS4: ='1'!$B$5 -> 3046098.5 | DT4: 0 | DU4: 1 | DV4: 0 | DW4: 0 | DX4: 0 | DY4: 0 | DZ4: 0 | EA4: 0 | EB4: 0 | EC4: 0 | ED4: =DS4+DT4+DV4-DW4+DX4-DY4+DZ4+EA4+EB4 -> 3046098.5 | EE4: ='1'!$B$15 -> 140203.94 | EF4: ='1'!$B$15 -> 140203.94 | EG4: ='1'!$B$21 -> 304609.75 | EH4: 0 | EI4: 0 | EJ4: 0 | EK4: =EF4+EG4+EH4-EI4-EJ4 -> 444813.69 | EL4: 0 | EM4: 0 | EN4: 0 | EO4: 0 | EP4: 0 | EQ4: =EM4+EN4-EO4-EP4 -> 0 | ER4: =ED4-EK4-EQ4 -> 2601284.8 | ES4: 0 | ET4: 0 | EZ4: Roads | FA4: {539308C0-87C6-4256-BD2D-FD6198DF208C}
A5: 1.1 - Cost increase due to incorrect t treatment of WIP, Retentions, VAT, etc. Cost increases from R3,046,098.51 to R3,807,623.14 | C5: Corrected values | D5: 2025/2026 | E5: 0 | F5: 10767 | G5: RD07909/000 | H5: RD07909 | I5: Unpaved Road | K5: Unpaved Road | O5: Property, Plant and Equipment | P5: Roads Infrastructure | Q5: Roads | R5: Unpaved Road | S5: Revaluation Module | U5: Unpaved Road | V5: Unpaved Road | W5: Property, plant and equipment | X5: Infrastructure assets | Y5: Roads infrastructure | Z5: Roads | AA5: Pavements | AB5: New | AC5: Infrastructure | AD5: Non Cash | AE5: EAR (Existing Asset Register) | AF5: 45306 | AG5: 45306 | AH5: 45306 | AL5: 45306 | AM5: 45473 | AN5: Lundi Knox Nxawe | AP5: 45473 | AS5: Good | AT5: No | AV5: No | AW5: 3807623.1 | AX5: =ER5 -> 3251606 | AY5: 0 | AZ5: 0 | BA5: Straight-line | BB5: 10 | BC5: 120 | BD5: 3650 | BE5: =BG5/365 -> 8.539726 | BF5: =BE5*12 -> 102.47671 | BG5: ='1'!$C$28 -> 3117 | BI5: Square Meter | BN5: 1 | BO5: 0 | BP5: 0 | BY5: Zanele Nontando Mbusi | BZ5: 830910xxxxxxx | CA5: Yes | CB5: Important | CC5: Meets requirements | CD5: Normal use | CE5: Very good | CF5: Moderate | CG5: Medium | CH5: Mnquma Local Municipality | CI5: Infrastructural Planning & Development | CJ5: Civil Services | CK5: Butterworth | CN5: Ward 1 | CU5: -32.188584 | CV5: 28.055332 | CW5: =DS5 -> 3807623.1 | CX5: 0 | DA5: 1 | DB5: 3036924.8 | DC5: 0 | DD5: 0 | DE5: 0 | DF5: 0 | DG5: 0 | DH5: 0 | DI5: 0 | DJ5: 0 | DK5: 0 | DL5: 0 | DM5: 0 | DN5: 0 | DO5: 0 | DP5: 0 | DQ5: Yes | DR5: ='1'!$C$5 -> 3807623.1 | DS5: ='1'!$C$5 -> 3807623.1 | DT5: 0 | DU5: 1 | DV5: 0 | DW5: 0 | DX5: 0 | DY5: 0 | DZ5: 0 | EA5: 0 | EB5: 0 | EC5: 0 | ED5: =DS5+DT5+DV5-DW5+DX5-DY5+DZ5+EA5+EB5 -> 3807623.1 | EE5: ='1'!$C$15 -> 175254.94 | EF5: ='1'!$C$15 -> 175254.94 | EG5: ='1'!$C$21 -> 380762.21 | EH5: 0 | EI5: 0 | EJ5: 0 | EK5: =EF5+EG5+EH5-EI5-EJ5 -> 556017.15 | EL5: 0 | EM5: 0 | EN5: 0 | EO5: 0 | EP5: 0 | EQ5: =EM5+EN5-EO5-EP5 -> 0 | ER5: =ED5-EK5-EQ5 -> 3251606 | ES5: 0 | ET5: 0 | EZ5: Roads | FA5: {539308C0-87C6-4256-BD2D-FD6198DF208C}
A6: 1.1 - Cost increase due to incorrect t treatment of WIP, Retentions, VAT, etc. Cost increases from R3,046,098.51 to R3,807,623.14 | C6: Net Correction | DS6: =DS4-DS5 -> -761524.63 | ED6: =ED4-ED5 -> -761524.63 | EE6: =EE4-EE5 -> -35051 | EF6: =EF4-EF5 -> -35051 | EG6: =EG4-EG5 -> -76152.46 | EH6: =EH4-EH5 -> 0 | EI6: =EI4-EI5 -> 0 | EJ6: =EJ4-EJ5 -> 0 | EK6: =EK4-EK5 -> -111203.46 | ER6: =ER4-ER5 -> -650321.17
A8: Description | C8: Current balance | D8: Corrected Balance | E8: Journal - Debit/ (Credit)
A9: Cost - Roads - Periods before 2024
A10: Cost - Roads - Period 2024 | C10: =DS4 -> 3046098.5 | D10: =DS5 -> 3807623.1 | E10: =D10-C10 -> 761524.63
A11: Cost - Roads - Period 2025
A12: Accumulated Surplus/WIP/Accruals/VAT before 2025 | E12: =-E10 -> -761524.63
A13: Accumulated Surplus/WIP/Accruals/VAT 2025
A14: Accumulated Depreciation - Roads - Before 2024
A15: Accumulated Depreciation - Roads - 2024 | C15: ='1'!$B$11 -> 140203.94 | D15: ='1'!$C$11 -> 175254.94 | E15: =C15-D15 -> -35051
A16: Accumulated Depreciation - Roads - 2025 | C16: ='1'!$B$21 -> 304609.75 | D16: ='1'!$C$21 -> 380762.21 | E16: =C16-D16 -> -76152.46
A17: Accumulated Surplus - Deprecation Charges before 2025 | C17: =C15 -> 140203.94 | D17: =D15 -> 175254.94 | E17: =D17-C17 -> 35051
A18: Accumulated Surplus - Deprecation Charges 2025 | C18: =C16 -> 304609.75 | D18: =D16 -> 380762.21 | E18: =D18-C18 -> 76152.46
A21: 1.2 - Cost decrease due to incorrect t treatment of WIP, Retentions, VAT, etc. Cost decreases from R3,046,098.51 to R2,284,573.88 | C21: Original values captured | D21: 2025/2026 | E21: 0 | F21: 10767 | G21: RD07909/000 | H21: RD07909 | I21: Unpaved Road | K21: Unpaved Road | O21: Property, Plant and Equipment | P21: Roads Infrastructure | Q21: Roads | R21: Unpaved Road | S21: Revaluation Module | U21: Unpaved Road | V21: Unpaved Road | W21: Property, plant and equipment | X21: Infrastructure assets | Y21: Roads infrastructure | Z21: Roads | AA21: Pavements | AB21: New | AC21: Infrastructure | AD21: Non Cash | AE21: EAR (Existing Asset Register) | AF21: 45306 | AG21: 45306 | AH21: 45306 | AL21: 45306 | AM21: 45473 | AN21: Lundi Knox Nxawe | AP21: 45473 | AS21: Good | AT21: No | AV21: No | AW21: 3046098.5 | AX21: =ER21 -> 2601284.8 | AY21: 0 | AZ21: 0 | BA21: Straight-line | BB21: 10 | BC21: 120 | BD21: 3650 | BE21: =BG21/365 -> 8.539726 | BF21: =BE21*12 -> 102.47671 | BG21: ='1'!$B$28 -> 3117 | BI21: Square Meter | BN21: 1 | BO21: 0 | BP21: 0 | BY21: Zanele Nontando Mbusi | BZ21: 830910xxxxxxx | CA21: Yes | CB21: Important | CC21: Meets requirements | CD21: Normal use | CE21: Very good | CF21: Moderate | CG21: Medium | CH21: Mnquma Local Municipality | CI21: Infrastructural Planning & Development | CJ21: Civil Services | CK21: Butterworth | CN21: Ward 1 | CU21: -32.188584 | CV21: 28.055332 | CW21: =DS21 -> 3046098.5 | CX21: 0 | DA21: 1 | DB21: 3036924.8 | DC21: 0 | DD21: 0 | DE21: 0 | DF21: 0 | DG21: 0 | DH21: 0 | DI21: 0 | DJ21: 0 | DK21: 0 | DL21: 0 | DM21: 0 | DN21: 0 | DO21: 0 | DP21: 0 | DQ21: Yes | DR21: ='1'!$B$5 -> 3046098.5 | DS21: ='1'!$B$5 -> 3046098.5 | DT21: 0 | DU21: 1 | DV21: 0 | DW21: 0 | DX21: 0 | DY21: 0 | DZ21: 0 | EA21: 0 | EB21: 0 | EC21: 0 | ED21: =DS21+DT21+DV21-DW21+DX21-DY21+DZ21+EA21+EB21 -> 3046098.5 | EE21: ='1'!$B$15 -> 140203.94 | EF21: ='1'!$B$15 -> 140203.94 | EG21: ='1'!$B$21 -> 304609.75 | EH21: 0 | EI21: 0 | EJ21: 0 | EK21: =EF21+EG21+EH21-EI21-EJ21 -> 444813.69 | EL21: 0 | EM21: 0 | EN21: 0 | EO21: 0 | EP21: 0 | EQ21: =EM21+EN21-EO21-EP21 -> 0 | ER21: =ED21-EK21-EQ21 -> 2601284.8 | ES21: 0 | ET21: 0 | EZ21: Roads | FA21: {539308C0-87C6-4256-BD2D-FD6198DF208C}
A22: 1.2 - Cost decrease due to incorrect t treatment of WIP, Retentions, VAT, etc. Cost decreases from R3,046,098.51 to R2,284,573.88 | C22: Corrected values | D22: 2025/2026 | E22: 0 | F22: 10767 | G22: RD07909/000 | H22: RD07909 | I22: Unpaved Road | K22: Unpaved Road | O22: Property, Plant and Equipment | P22: Roads Infrastructure | Q22: Roads | R22: Unpaved Road | S22: Revaluation Module | U22: Unpaved Road | V22: Unpaved Road | W22: Property, plant and equipment | X22: Infrastructure assets | Y22: Roads infrastructure | Z22: Roads | AA22: Pavements | AB22: New | AC22: Infrastructure | AD22: Non Cash | AE22: EAR (Existing Asset Register) | AF22: 45306 | AG22: 45306 | AH22: 45306 | AL22: 45306 | AM22: 45473 | AN22: Lundi Knox Nxawe | AP22: 45473 | AS22: Good | AT22: No | AV22: No | AW22: 3807623.1 | AX22: =ER22 -> 1950963.6 | AY22: 0 | AZ22: 0 | BA22: Straight-line | BB22: 10 | BC22: 120 | BD22: 3650 | BE22: =BG22/365 -> 8.539726 | BF22: =BE22*12 -> 102.47671 | BG22: ='1'!$D$28 -> 3117 | BI22: Square Meter | BN22: 1 | BO22: 0 | BP22: 0 | BY22: Zanele Nontando Mbusi | BZ22: 830910xxxxxxx | CA22: Yes | CB22: Important | CC22: Meets requirements | CD22: Normal use | CE22: Very good | CF22: Moderate | CG22: Medium | CH22: Mnquma Local Municipality | CI22: Infrastructural Planning & Development | CJ22: Civil Services | CK22: Butterworth | CN22: Ward 1 | CU22: -32.188584 | CV22: 28.055332 | CW22: =DS22 -> 2284573.9 | CX22: 0 | DA22: 1 | DB22: 3036924.8 | DC22: 0 | DD22: 0 | DE22: 0 | DF22: 0 | DG22: 0 | DH22: 0 | DI22: 0 | DJ22: 0 | DK22: 0 | DL22: 0 | DM22: 0 | DN22: 0 | DO22: 0 | DP22: 0 | DQ22: Yes | DR22: ='1'!$C$5 -> 3807623.1 | DS22: ='1'!$D$5 -> 2284573.9 | DT22: 0 | DU22: 1 | DV22: 0 | DW22: 0 | DX22: 0 | DY22: 0 | DZ22: 0 | EA22: 0 | EB22: 0 | EC22: 0 | ED22: =DS22+DT22+DV22-DW22+DX22-DY22+DZ22+EA22+EB22 -> 2284573.9 | EE22: ='1'!$D$15 -> 105152.94 | EF22: ='1'!$D$15 -> 105152.94 | EG22: ='1'!$D$21 -> 228457.29 | EH22: 0 | EI22: 0 | EJ22: 0 | EK22: =EF22+EG22+EH22-EI22-EJ22 -> 333610.23 | EL22: 0 | EM22: 0 | EN22: 0 | EO22: 0 | EP22: 0 | EQ22: =EM22+EN22-EO22-EP22 -> 0 | ER22: =ED22-EK22-EQ22 -> 1950963.6 | ES22: 0 | ET22: 0 | EZ22: Roads | FA22: {539308C0-87C6-4256-BD2D-FD6198DF208C}
A23: 1.2 - Cost decrease due to incorrect t treatment of WIP, Retentions, VAT, etc. Cost decreases from R3,046,098.51 to R2,284,573.88 | C23: Net Correction | DS23: =DS21-DS22 -> 761524.63 | ED23: =ED21-ED22 -> 761524.63 | EE23: =EE21-EE22 -> 35051 | EF23: =EF21-EF22 -> 35051 | EG23: =EG21-EG22 -> 76152.46 | EH23: =EH21-EH22 -> 0 | EI23: =EI21-EI22 -> 0 | EJ23: =EJ21-EJ22 -> 0 | EK23: =EK21-EK22 -> 111203.46 | ER23: =ER21-ER22 -> 650321.17
A25: Description | C25: Current balance | D25: Corrected Balance | E25: Journal - Debit/ (Credit)
A26: Cost - Roads - Periods before 2024
A27: Cost - Roads - Period 2024 | C27: =DS21 -> 3046098.5 | D27: =DS22 -> 2284573.9 | E27: =D27-C27 -> -761524.63
A28: Cost - Roads - Period 2025
A29: Accumulated Surplus/WIP/Accruals/VAT before 2025 | E29: =-E27 -> 761524.63
A30: Accumulated Surplus/WIP/Accruals/VAT 2025 | E30: =-E28 -> 0
A31: Accumulated Depreciation - Roads - Before 2024
A32: Accumulated Depreciation - Roads - 2024 | C32: ='1'!$B$11 -> 140203.94 | D32: ='1'!$D$11 -> 105152.94 | E32: =C32-D32 -> 35051
A33: Accumulated Depreciation - Roads - 2025 | C33: ='1'!$B$21 -> 304609.75 | D33: ='1'!$D$21 -> 228457.29 | E33: =C33-D33 -> 76152.46
A34: Accumulated Surplus - Deprecation Charges before 2025 | C34: =C32 -> 140203.94 | D34: =D32 -> 105152.94 | E34: =D34-C34 -> -35051
A35: Accumulated Surplus - Deprecation Charges 2025 | C35: =C33 -> 304609.75 | D35: =D33 -> 228457.29 | E35: =D35-C35 -> -76152.46
D39: FinancialYear | E39: FinancialPeriod | F39: AssetRegisterItemID | G39: MunicipalAssetID | H39: ParentAssetRegisterItem_ID | I39: MainAssetDescription | J39: MainAssetID | K39: AssetDescription | L39: OldBarcode | M39: Barcode | N39: ImageRef | O39: AssetType | P39: AssetCategory | Q39: AssetSubCategory | R39: AssetClass | S39: MeasurementType_ID2 | T39: AssetStatus | U39: CIDMSSubComponentType | V39: CIDMSComponentType | W39: CIDMSAccountingGroup | X39: CIDMSSubAccountingGroup | Y39: CIDMSAssetClass | Z39: CIDMSAssetGroupType | AA39: CIDMSAssetType | AB39: NatureOfAddition | AC39: InfrastructurOrNonInfrastructure | AD39: CashNonCashGeneratingUnit | AE39: FinancialStatus | AF39: TakeOnDate | AG39: AquisitionDate | AH39: System_In_Service_Date | AI39: DisposalDate | AJ39: DisposalReason | AK39: Impairment_Date | AL39: DateModified | AM39: VerificationDate | AN39: VerificationDoneBy | AO39: YearConstructed | AP39: CommisioningDate | AQ39: ConstructionMaterial | AR39: ForecastReplacementYear | AS39: AssetCondition | AT39: InsuranceCover | AU39: InsurancePolicy | AV39: Warranty | AW39: CurrentReplacementCostCRC | AX39: DepreciatedReplacementCostDRC | AY39: AnnualisedMaintenanceCRC | AZ39: AnnualMaintenanceBudgetNeed | BA39: DepreciationMethod | BB39: UsefulLifeYearComponent | BC39: UsefulLifeMonthComponent | BD39: UsefulLifeDaysComponent | BE39: Remaining_Useful_Life_Year | BF39: Remaining_Useful_Life_Months | BG39: Remaining_Useful_Life_Days | BH39: RemainingUsefulllifeAtTakeon | BI39: UOM | BJ39: Dim1 | BK39: Dim2 | BL39: Dim3 | BM39: DimensionQuantity | BN39: Quantity | BO39: Diameter | BP39: Capacity | BQ39: SGNumberChange_ID | BR39: DeedNumber | BS39: ErfNumber | BT39: ErfSizeM2 | BU39: PortionNumber | BV39: UnitNumber | BW39: RegistrationNumber | BX39: SerialNumber | BY39: CustodianName | BZ39: CustodianIdNumber | CA39: BasicMunicipalServices | CB39: CriticalityGrade | CC39: PerformanceGrade | CD39: UtilisationGrade | CE39: InfrastructureHealthGrade | CF39: ConsequenceOfFailure | CG39: Risk | CH39: AssetOwnership | CI39: Department | CJ39: Division | CK39: Town | CL39: StreetName | CM39: Building | CN39: Ward | CO39: Zoning | CP39: FloorArea | CQ39: RoomNumber | CR39: Suburb | CS39: WellKnownTextWKT | CT39: GISID | CU39: Latitude | CV39: Longitude | CW39: FundingSourceAmount | CX39: FundingSourceNumber | CY39: FundType | CZ39: CostOfAddition | DA39: Revaluation_Date | DB39: Revaluation_Value | DC39: Accumulated_Revalutions_Opening_Balance | DD39: Revaluation_Reserve_Impairments_OpeningBalance | DE39: Revaluation_Reserve_Impairments | DF39: Revaluation_Reserve_Impairment_Reversals | DG39: Revaluation_Reserve_Impairments_ClosingBalance | DH39: Revaluation_Reserve_Revaluations | DI39: Revaluation_Reserve_Disposals | DJ39: Refurb_Revaluation | DK39: Accumulated_Revaluation_Closing_Balance | DL39: Movement_In_Revaluation_Reserve | DM39: DepreciationOffsetOpeningBalance | DN39: Depreciation_Offset | DO39: DepreciationOffsetClosingBalance | DP39: Revaluation_Surplus_Deficit | DQ39: Deemed_Cost | DR39: Cost_OpeningBalance | DS39: Cost_RestatedOpeningBalance | DT39: Cost_Acquisitions | DU39: Cost_RisidualValue | DV39: WorkInProgress | DW39: TransferFromAmount | DX39: TransferToAmount | DY39: RefurbishmentCredit | DZ39: RefurbishmentDebit | EA39: Cost_FairValueAdjustment | EB39: Revaluation_Adjustment | EC39: Cost_Disposal | ED39: Cost_ClosingBalance | EE39: AccumulatedDepreciation_OpeningBalance | EF39: AccumulatedDepreciation_RestatedOpeningBalance | EG39: AccumulatedDepreciation_Depreciation | EH39: DepreciationAdjustments | EI39: AccumulatedDepreciation_Disposal | EJ39: Refurb_Depreciation | EK39: AccumulatedDepreciation_ClosingBalance | EL39: AccumulatedImpairment_OpeningBalance | EM39: AccumulatedImpairment_RestatedOpeningBalance | EN39: AccumulatedImpairmentImpairment | EO39: AccumulatedImpairment_ReversalOfImpairment | EP39: AccumulatedImpairment_Disposal | EQ39: AccumulatedImpairment_ClosingBalance | ER39: CarryingAmount | ES39: Disposal_Proceeds | ET39: Disposal_Profit_Loss | EU39: DonorIDRegistrationNumberParastatalCode | EV39: DonorNameCompanyRegistrationNumberParastatalName | EW39: Date_Donated | EX39: Make | EY39: Model | EZ39: Custom_1 | FA39: Custom_2 | FB39: Custom_3 | FC39: Custom_4 | FD39: Custom_5 | FE39: Custom_6 | FF39: Custom_7 | FG39: Custom_8 | FH39: Custom_9
A40: 2.1 - Asset was revalued on 30 June 2023. The balances at 30 June 2023 = Revaluation reserv = (5,660,048.60), Cost = 12,164,247.00, Acc Dep = (6,020,788.83), RUL = 5534, EUL = 10957.5, Value = 6,143,458.17 Change valuation to R7,500,500.00 | C40: Original values captured | D40: 2024/2025 | E40: 0 | F40: 7424 | G40: RD06804/000 | H40: RD06804 | I40: Bridge Sub Structure | K40: Bridge Sub Structure | O40: Property, Plant and Equipment | P40: Roads Infrastructure | Q40: Roads | R40: Bridge Sub Structure | S40: Revaluation Module | U40: Bridge Sub Structure | V40: Bridge Sub Structure | W40: Property, plant and equipment | X40: Infrastructure assets | Y40: Roads infrastructure | Z40: Road structures | AA40: Road bridges | AB40: New | AC40: Infrastructure | AD40: Non Cash | AE40: EAR (Existing Asset Register) | AF40: 45580 | AG40: 41456 | AH40: 45473 | AL40: 45838.958 | AM40: 45473 | AN40: Lundi Knox Nxawe | AP40: 45473 | AS40: Good | AT40: No | AV40: No | AW40: 12164247 | AX40: 5378818.8 | AY40: 0 | AZ40: 0 | BA40: Straight-line | BB40: 30 | BC40: =BB40*12 -> 360 | BD40: 10957.5 | BE40: =BG40/365 -> 13.158904 | BF40: =BE40*12 -> 157.90685 | BG40: ='2'!$C$40 -> 4803 | BI40: Each | BN40: 1 | BO40: 0 | BP40: 0 | BY40: Zanele Nontando Mbusi | BZ40: 830910xxxxxxx | CA40: Yes | CB40: Important | CC40: Meets requirements | CD40: Normal use | CE40: Good | CF40: Moderate | CG40: Medium | CH40: Mnquma Local Municipality | CI40: Infrastructural Planning & Development | CJ40: Civil Services | CK40: Butterworth | CN40: Ward 1 | CU40: -32.208988 | CV40: 27.794534 | CW40: 1162063.6 | CX40: 0 | DA40: 45107 | DB40: ='2'!$C$9 -> 6143458.2 | DC40: ='2'!$C$8 -> 5660048.6 | DD40: 0 | DE40: 0 | DF40: 0 | DG40: 0 | DH40: 0 | DI40: 0 | DJ40: 0 | DK40: =DC40-DO40 -> 4912398.5 | DL40: 0 | DM40: ='2'!$C$18 -> 374336.43 | DN40: ='2'!$C$31 -> 373313.65 | DO40: =DM40+DN40 -> 747650.08 | DP40: =DK40 -> 4912398.5 | DQ40: Yes | DR40: ='2'!$C$5 -> 12164247 | DS40: ='2'!$C$5 -> 12164247 | DT40: 0 | DU40: 1 | DV40: 0 | DW40: 0 | DX40: 0 | DY40: 0 | DZ40: 0 | EA40: 0 | EB40: 0 | EC40: 0 | ED40: 12164247 | EE40: ='2'!$C$23 -> 6427096.3 | EF40: ='2'!$C$23 -> 6427096.3 | EG40: ='2'!$C$30 -> 405197.3 | EH40: 0 | EI40: 0 | EJ40: 0 | EK40: =EF40+EG40 -> 6832293.6 | EL40: 0 | EM40: 0 | EN40: 0 | EO40: 0 | EP40: 0 | EQ40: 0 | ER40: =ED40-EK40 -> 5331953.4 | ES40: 0 | ET40: 0 | EZ40: Roads | FA40: {8BEA2AE3-F204-4829-8828-5B4A7F3E8976}
A41: 2.1 - Asset was revalued on 30 June 2023. The balances at 30 June 2023 = Revaluation reserv = (5,660,048.60), Cost = 12,164,247.00, Acc Dep = (6,020,788.83), RUL = 5534, EUL = 10957.5, Value = 6,143,458.17 Change valuation to R7,500,500.00 | C41: Corrected values | D41: 2024/2025 | E41: 0 | F41: 7424 | G41: RD06804/000 | H41: RD06804 | I41: Bridge Sub Structure | K41: Bridge Sub Structure | O41: Property, Plant and Equipment | P41: Roads Infrastructure | Q41: Roads | R41: Bridge Sub Structure | S41: Revaluation Module | U41: Bridge Sub Structure | V41: Bridge Sub Structure | W41: Property, plant and equipment | X41: Infrastructure assets | Y41: Roads infrastructure | Z41: Road structures | AA41: Road bridges | AB41: New | AC41: Infrastructure | AD41: Non Cash | AE41: EAR (Existing Asset Register) | AF41: 45580 | AG41: 41456 | AH41: 45473 | AL41: 45838.958 | AM41: 45473 | AN41: Lundi Knox Nxawe | AP41: 45473 | AS41: Good | AT41: No | AV41: No | AW41: 12164247 | AX41: 5378818.8 | AY41: 0 | AZ41: 0 | BA41: Straight-line | BB41: 30 | BC41: =BB41*12 -> 360 | BD41: 10957.5 | BE41: =BG41/365 -> 13.158904 | BF41: =BE41*12 -> 157.90685 | BG41: ='2'!$D$40 -> 4803 | BI41: Each | BN41: 1 | BO41: 0 | BP41: 0 | BY41: Zanele Nontando Mbusi | BZ41: 830910xxxxxxx | CA41: Yes | CB41: Important | CC41: Meets requirements | CD41: Normal use | CE41: Good | CF41: Moderate | CG41: Medium | CH41: Mnquma Local Municipality | CI41: Infrastructural Planning & Development | CJ41: Civil Services | CK41: Butterworth | CN41: Ward 1 | CU41: -32.208988 | CV41: 27.794534 | CW41: 1162063.6 | CX41: 0 | DA41: 45107 | DB41: ='2'!$D$9 -> 7500500 | DC41: ='2'!$D$8 -> 7017090.4 | DD41: 0 | DE41: 0 | DF41: 0 | DG41: 0 | DH41: 0 | DI41: 0 | DJ41: 0 | DK41: =DC41-DO41 -> 6090185.3 | DL41: 0 | DM41: ='2'!$D$18 -> 464086.57 | DN41: ='2'!$D$31 -> 462818.58 | DO41: =DM41+DN41 -> 926905.15 | DP41: =DK41 -> 6090185.3 | DQ41: Yes | DR41: ='2'!$D$5 -> 14851234 | DS41: ='2'!$D$5 -> 14851234 | DT41: 0 | DU41: 1 | DV41: 0 | DW41: 0 | DX41: 0 | DY41: 0 | DZ41: 0 | EA41: 0 | EB41: 0 | EC41: 0 | ED41: =DS41 -> 14851234 | EE41: ='2'!$D$23 -> 7846791.5 | EF41: ='2'!$D$23 -> 7846791.5 | EG41: ='2'!$D$30 -> 494702.23 | EH41: 0 | EI41: 0 | EJ41: 0 | EK41: =EF41+EG41 -> 8341493.8 | EL41: 0 | EM41: 0 | EN41: 0 | EO41: 0 | EP41: 0 | EQ41: 0 | ER41: =ED41-EK41 -> 6509740.2 | ES41: 0 | ET41: 0 | EZ41: Roads | FA41: {8BEA2AE3-F204-4829-8828-5B4A7F3E8976}
A43: Revaluation reserve balance | B43: -5660048.6 | DC43: =DC40-DC41 -> -1357041.8 | DD43: =DD40-DD41 -> 0 | DE43: =DE40-DE41 -> 0 | DF43: =DF40-DF41 -> 0 | DG43: =DG40-DG41 -> 0 | DH43: =DH40-DH41 -> 0 | DI43: =DI40-DI41 -> 0 | DJ43: =DJ40-DJ41 -> 0 | ... DP43: =DP40-DP41 -> -1177786.8 | DR43: =DR40-DR41 -> -2686987 | DS43: =DS40-DS41 -> -2686987 | DT43: =DT40-DT41 -> 0 | DU43: =DU40-DU41 -> 0 | DV43: =DV40-DV41 -> 0 | DW43: =DW40-DW41 -> 0 | DX43: =DX40-DX41 -> 0 | DY43: =DY40-DY41 -> 0 | ... ED43: =ED40-ED41 -> -2686987 | EF43: =EF40-EF41 -> -1419695.3 | EG43: =EG40-EG41 -> -89504.93 | EH43: =EH40-EH41 -> 0 | EI43: =EI40-EI41 -> 0 | EJ43: =EJ40-EJ41 -> 0 | EK43: =EK40-EK41 -> -1509200.2 | ER43: =ER40-ER41 -> -1177786.8
A44: Cost | B44: 12164247
A45: Accumulated Depreciation | B45: 6020788.8 | C45: 7500500 | D45: =ROUND(C45/B47*B46,2) -> 14851234 | E45: =D45-C45 -> 7350734 | F45: =C45-C46 -> 1357041.8
A46: EUL | B46: 10957.5 | C46: =B44-B45 -> 6143458.2 | D46: =ROUND(C46/5534*10957.5,2) -> 12164247 | E46: =D46-C46 -> 6020788.8 | F46: =-B43+F45 -> 7017090.4
A47: RUL | B47: 5534
A48: Carrying value before revaluation | B48: 4318557.7
A49: Revaluation reserve balance before revalaution | B49: -3835148.2
A50: Value adjustment | B50: =C46-B48 -> 1824900.4
...

Sheet 1
C2: 1.1 | D2: 1.2
B3: Normal | C3: Cost increase due to incorrect t treatment of WIP, Retentions, VAT, etc. Cost increases from R3,046,098.51 to R3,807,623.14 | D3: Cost decrease due to incorrect t treatment of WIP, Retentions, VAT, etc. Cost decreases from R3,046,098.51 to R2,284,573.88
A5: Cost | B5: 3046098.5 | C5: 3807623.1 | D5: 2284573.9
A6: EUL | B6: 3650 | C6: 3650 | D6: 3650
A7: Acquisition date | B7: 45306 | C7: 45306 | D7: 45306
A8: Residual Value | B8: 1 | C8: 1 | D8: 1
A9: Year 1 | B9: 45473 | C9: 45473 | D9: 45473
A10: Days in use at 30 June 2024 | B10: =B9-B7+1 -> 168 | C10: =C9-C7+1 -> 168 | D10: =D9-D7+1 -> 168
A11: Accumulated Depreciation 20 June 2024 | B11: =ROUND((B5-B8)/B6*B10,2) -> 140203.94 | C11: =ROUND((C5-C8)/C6*C10,2) -> 175254.94 | D11: =ROUND((D5-D8)/D6*D10,2) -> 105152.94
A14: Cost | B14: =B5 -> 3046098.5 | C14: =C5 -> 3807623.1 | D14: =D5 -> 2284573.9
A15: Accumulated Depreciation | B15: =B11 -> 140203.94 | C15: =C11 -> 175254.94 | D15: =D11 -> 105152.94
A16: Accumulated Impairment
A17: Carrying Value | B17: =B14-B15-B16 -> 2905894.6 | C17: =C14-C15-C16 -> 3632368.2 | D17: =D14-D15-D16 -> 2179420.9
A19: RUL | B19: =B6-B10 -> 3482 | C19: =C6-C10 -> 3482 | D19: =D6-D10 -> 3482
A21: Depreciation 2025 | B21: =ROUND((B17-B8)/B19*365,2) -> 304609.75 | C21: =ROUND((C17-C8)/C19*365,2) -> 380762.21 | D21: =ROUND((D17-D8)/D19*365,2) -> 228457.29
A23: Cost | B23: =B5 -> 3046098.5 | C23: =C5 -> 3807623.1 | D23: =D5 -> 2284573.9
A24: Accumulated Depreciation | B24: =B15+B21 -> 444813.69 | C24: =C15+C21 -> 556017.15 | D24: =D15+D21 -> 333610.23
A25: Accumulated Impairment
A26: Carrying Value | B26: =B23-B24-B25 -> 2601284.8 | C26: =C23-C24-C25 -> 3251606 | D26: =D23-D24-D25 -> 1950963.6
B28: =B19-365 -> 3117 | C28: =C19-365 -> 3117 | D28: =D19-365 -> 3117

Sheet 2
D2: 2.1 | F2: 2.2
B3: Before revaluation | C3: Revaluation 30 June 2023 | D3: Asset was revalued on 30 June 2023. The balances at 30 June 2023 = Revaluation reserv = (5,660,048.60), Cost = 12,164,247.00, Acc Dep = (6,020,788.83), RUL = 5534, EUL = 10957.5, Value = 6,143,458.17 Change valuation to R7,500,500.00 | F3: Asset was revalued on 30 June 2023. The balances at 30 June 2023 = Revaluation reserv = (5,660,048.60), Cost = 12,164,247.00, Acc Dep = (6,020,788.83), RUL = 5534, EUL = 10957.5, Value = 6,143,458.17 Change valuation to R5,500,500.00
A5: Cost | B5: 14067804 | C5: 12164247 | D5: =ROUND(D9/D12*D11,2) -> 14851234 | E5: =D5-C5 -> 2686987 | F5: =ROUND(F9/F12*F11,2) -> 10891169 | G5: =F5-C5 -> -1273078.1
A6: Accumulated depreciation | B6: 9749246.1 | C6: 6020788.8 | D6: =D5-D9 -> 7350734 | E6: =-D6+C6 -> -1329945.1 | F6: =F5-F9 -> 5390668.9 | G6: =-F6+C6 -> 630119.92
A7: Accumulated impairment losses
A8: Revaluation reserve | B8: 3835148.2 | C8: 5660048.6 | D8: =D9-C9+C8 -> 7017090.4 | E8: =-D8+C8 -> -1357041.8 | F8: =F9-C9+C8 -> 5017090.4 | G8: =-F8+C8 -> 642958.17
A9: Carrying Value | B9: =B5-B6 -> 4318557.7 | C9: =C5-C6 -> 6143458.2 | D9: 7500500 | E9: =SUM(E5:E8) -> 0 | F9: 5500500 | G9: =SUM(G5:G8) -> 0
A11: EUL | C11: 10957.5 | D11: 10957.5 | F11: 10957.5
A12: RUL | C12: 5534 | D12: 5534 | F12: 5534
A13: Residual Value | C13: 1 | D13: 1 | F13: 1
A14: Depreciation start date | C14: 45108 | D14: 45108 | F14: 45108
A15: Year 1 | C15: 45473 | D15: 45473 | F15: 45473
A16: Day is use 30 June 2024 | C16: =C15-C14+1 -> 366 | D16: =D15-D14+1 -> 366 | F16: =F15-F14+1 -> 366
A17: Accumulated Depreciation 30 June 2024 | C17: =ROUND((C9-C13)/C12*C16,2) -> 406307.43 | D17: =ROUND((D9-D13)/D12*D16,2) -> 496057.58 | F17: =ROUND((F9-F13)/F12*F16,2) -> 363784.36
A18: Depreciation offset 30 June 2024 | C18: =ROUND(C8/C12*C16,2) -> 374336.43 | D18: =ROUND(D8/D12*D16,2) -> 464086.57 | F18: =ROUND(F8/F12*F16,2) -> 331813.35
A22: Cost | C22: =C5 -> 12164247 | D22: =D5 -> 14851234 | F22: =F5 -> 10891169
A23: Accumulated Depreciation | C23: =C6+C17 -> 6427096.3 | D23: =D6+D17 -> 7846791.5 | F23: =F6+F17 -> 5754453.3
A24: Accumulated Impairment
A25: Carrying Value | C25: =C22-C23-C24 -> 5737150.7 | D25: =D22-D23-D24 -> 7004442.4 | F25: =F22-F23-F24 -> 5136715.6
A26: Revaluation Reserve | C26: =C8-C18 -> 5285712.2 | D26: =D8-D18 -> 6553003.9 | F26: =F8-F18 -> 4685277.1
A28: RUL | C28: =C12-C16 -> 5168 | D28: =D12-D16 -> 5168 | F28: =F12-F16 -> 5168
A30: Depreciation 2025 | C30: =ROUND((C25-C13)/C28*365,2) -> 405197.3 | D30: =ROUND((D25-D13)/D28*365,2) -> 494702.23 | F30: =ROUND((F25-F13)/F28*365,2) -> 362790.41
A31: Depreciation offset 2025 | C31: =ROUND(C26/C28*365,2) -> 373313.65 | D31: =ROUND(D26/D28*365,2) -> 462818.58 | F31: =ROUND(F26/F28*365,2) -> 330906.76
A34: Cost | C34: =C22 -> 12164247 | D34: =D22 -> 14851234 | F34: =F22 -> 10891169
A35: Accumulated Depreciation | C35: =C23+C30 -> 6832293.6 | D35: =D23+D30 -> 8341493.8 | F35: =F23+F30 -> 6117243.7
A36: Accumulated Impairment
A37: Carrying Value | C37: =C34-C35-C36 -> 5331953.4 | D37: =D34-D35-D36 -> 6509740.2 | F37: =F34-F35-F36 -> 4773925.2
A38: Revaluation Reserve | C38: =C26-C31 -> 4912398.5 | D38: =D26-D31 -> 6090185.3 | F38: =F26-F31 -> 4354370.3
C40: =C28-365 -> 4803 | D40: =D28-365 -> 4803 | F40: =F28-365 -> 4803

Sheet 3
C2: 3.1 | D2: 3.2
B3: Normal | C3: Asset at deemed cost, acquisition date captured incorrectly at 2024/06/20 instead of 2024/01/15 | D3: Cost decrease due to incorrect t treatment of WIP, Retentions, VAT, etc. Cost decreases from R3,046,098.51 to R2,284,573.88
A5: Cost | B5: 3046098.5 | C5: 3046098.5 | D5: 3046098.5
A6: EUL | B6: 3650 | C6: 3650 | D6: 3650
A7: Acquisition date | B7: 45463 | C7: 45306 | D7: 45472
A8: Residual Value | B8: 1 | C8: 1 | D8: 1
A9: Year 1 | B9: 45473 | C9: 45473 | D9: 45473
A10: Days in use at 30 June 2024 | B10: =B9-B7+1 -> 11 | C10: =C9-C7+1 -> 168 | D10: =D9-D7+1 -> 2
A11: Accumulated Depreciation 20 June 2024 | B11: =ROUND((B5-B8)/B6*B10,2) -> 9180.02 | C11: =ROUND((C5-C8)/C6*C10,2) -> 140203.94 | D11: =ROUND((D5-D8)/D6*D10,2) -> 1669.09
A14: Cost | B14: =B5 -> 3046098.5 | C14: =C5 -> 3046098.5 | D14: =D5 -> 3046098.5
A15: Accumulated Depreciation | B15: =B11 -> 9180.02 | C15: =C11 -> 140203.94 | D15: =D11 -> 1669.09
A16: Accumulated Impairment
A17: Carrying Value | B17: =B14-B15-B16 -> 3036918.5 | C17: =C14-C15-C16 -> 2905894.6 | D17: =D14-D15-D16 -> 3044429.4
A19: RUL | B19: =B6-B10 -> 3639 | C19: =C6-C10 -> 3482 | D19: =D6-D10 -> 3648
A21: Depreciation 2025 | B21: =ROUND((B17-B8)/B19*365,2) -> 304609.75 | C21: =ROUND((C17-C8)/C19*365,2) -> 304609.75 | D21: =ROUND((D17-D8)/D19*365,2) -> 304609.75
A23: Cost | B23: =B5 -> 3046098.5 | C23: =C5 -> 3046098.5 | D23: =D5 -> 3046098.5
A24: Accumulated Depreciation | B24: =B15+B21 -> 313789.77 | C24: =C15+C21 -> 444813.69 | D24: =D15+D21 -> 306278.84
A25: Accumulated Impairment
A26: Carrying Value | B26: =B23-B24-B25 -> 2732308.7 | C26: =C23-C24-C25 -> 2601284.8 | D26: =D23-D24-D25 -> 2739819.7
B28: =B19-365 -> 3274 | C28: =C19-365 -> 3117 | D28: =D19-365 -> 3283

Sheet 4
B3: Before | C3: Asset not recognised - Newly identified, Donated asset, etc - FV - take on date 20 June 2024, deemed cost R3,046,098.51, RUL at take on is 2950 days
A5: Cost | C5: 3046098.5
A6: EUL | C6: 2950
A7: Acquisition date | C7: 45463
A8: Residual Value | C8: 1
A9: Year 1 | C9: 45473
A10: Days in use at 30 June 2024 | C10: =C9-C7+1 -> 11
A11: Accumulated Depreciation 20 June 2024 | C11: =ROUND((C5-C8)/C6*C10,2) -> 11358.33
A14: Cost | B14: =B5 -> 0 | C14: =C5 -> 3046098.5
A15: Accumulated Depreciation | B15: =B11 -> 0 | C15: =C11 -> 11358.33
A16: Accumulated Impairment
A17: Carrying Value | B17: =B14-B15-B16 -> 0 | C17: =C14-C15-C16 -> 3034740.2
A19: RUL | C19: =C6-C10 -> 2939
A21: Depreciation 2025 | C21: =ROUND((C17-C8)/C19*365,2) -> 376890.03
A23: Cost | C23: =C5 -> 3046098.5
A24: Accumulated Depreciation | C24: =C15+C21 -> 388248.36
A25: Accumulated Impairment
A26: Carrying Value | B26: =B23-B24-B25 -> 0 | C26: =C23-C24-C25 -> 2657850.1
C28: =C19-365 -> 2574

Sheet 5
C2: 5.1 & 5.2 | D2: 5.2
B3: Normal | C3: Residual value not captured - Should be R301,609.85 | D3: Residual value captured as R500,100.00 instead of R304,610.00
A5: Cost | B5: 3046098.5 | C5: 3046098.5 | D5: 3046098.5
A6: EUL | B6: 3650 | C6: 3650 | D6: 3650
A7: Acquisition date | B7: 45463 | C7: 45463 | D7: 45463
A8: Residual Value | B8: 1 | C8: 304609.85 | D8: 500100
A9: Year 1 | B9: 45473 | C9: 45473 | D9: 45473
A10: Days in use at 30 June 2024 | B10: =B9-B7+1 -> 11 | C10: =C9-C7+1 -> 11 | D10: =D9-D7+1 -> 11
A11: Accumulated Depreciation 20 June 2024 | B11: =ROUND((B5-B8)/B6*B10,2) -> 9180.02 | C11: =ROUND((C5-C8)/C6*C10,2) -> 8262.02 | D11: =ROUND((D5-D8)/D6*D10,2) -> 7672.87
A14: Cost | B14: =B5 -> 3046098.5 | C14: =C5 -> 3046098.5 | D14: =D5 -> 3046098.5
A15: Accumulated Depreciation | B15: =B11 -> 9180.02 | C15: =C11 -> 8262.02 | D15: =D11 -> 7672.87
A16: Accumulated Impairment
A17: Carrying Value | B17: =B14-B15-B16 -> 3036918.5 | C17: =C14-C15-C16 -> 3037836.5 | D17: =D14-D15-D16 -> 3038425.6
A19: RUL | B19: =B6-B10 -> 3639 | C19: =C6-C10 -> 3639 | D19: =D6-D10 -> 3639
A21: Depreciation 2025 | B21: =ROUND((B17-B8)/B19*365,2) -> 304609.75 | C21: =ROUND((C17-C8)/C19*365,2) -> 274148.87 | D21: =ROUND((D17-D8)/D19*365,2) -> 254599.85
A23: Cost | B23: =B5 -> 3046098.5 | C23: =C5 -> 3046098.5 | D23: =D5 -> 3046098.5
A24: Accumulated Depreciation | B24: =B15+B21 -> 313789.77 | C24: =C15+C21 -> 282410.89 | D24: =D15+D21 -> 262272.72
A25: Accumulated Impairment
A26: Carrying Value | B26: =B23-B24-B25 -> 2732308.7 | C26: =C23-C24-C25 -> 2763687.6 | D26: =D23-D24-D25 -> 2783825.8
B28: =B19-365 -> 3274 | C28: =C19-365 -> 3274 | D28: =D19-365 -> 3274

Sheet 6
C2: 6.1 | E2: 6.2 | F2: 6.3
B3: Normal | C3: Impaired tp 1200000 | E3: Impaired tp 1400000 | F3: Impaired tp 1000000
A5: Cost | B5: 3046098.5 | C5: 3046098.5 | E5: 3046098.5 | F5: 3046098.5
A6: EUL | B6: 3650 | C6: 3650 | E6: 3650 | F6: 3650
A7: Acquisition date | B7: 45306 | C7: 45306 | E7: 45306 | F7: 45306
A8: Residual Value | B8: 1 | C8: 1 | E8: 1 | F8: 1
A9: Impairment date | B9: 45463 | C9: 45463 | E9: 45463 | F9: 45463
B10: 45473 | C10: 45473 | E10: 45473 | F10: 45473
A11: Day is use 20 June 2024 | B11: =B9-B7+1 -> 158 | C11: =C9-C7+1 -> 158 | E11: =E9-E7+1 -> 158 | F11: =F9-F7+1 -> 158
A12: Days in use 20 June to 30 June | B12: =B10-B7+1-B11 -> 10 | C12: =C10-C7+1-C11 -> 10 | E12: =E10-E7+1-E11 -> 10 | F12: =F10-F7+1-F11 -> 10
A13: Accumulated Depreciation 20 June 2024 | B13: =ROUND((B5-B8)/B6*B11,2) -> 131858.47 | C13: =ROUND((C5-C8)/C6*C11,2) -> 131858.47 | E13: =ROUND((E5-E8)/E6*E11,2) -> 131858.47 | F13: =ROUND((F5-F8)/F6*F11,2) -> 131858.47
A15: Impairment | C15: =C5-C13-1200000 -> 1714240 | E15: =E5-E13-1400000 -> 1514240 | F15: =F5-F13-1000000 -> 1914240
A16: RUL after impairment | C16: 730 | E16: 730 | F16: 730
A18: Depreciation 21 June to 30 June | B18: =ROUND((B5-B8)/B6*B12,2) -> 8345.47 | C18: =ROUND((C5-C13-C15-C8)/C16*C12,2) -> 16438.34 | E18: =ROUND((E5-E13-E15-E8)/E16*E12,2) -> 19178.07 | F18: =ROUND((F5-F13-F15-F8)/F16*F12,2) -> 13698.62
A21: Cost | B21: =B5 -> 3046098.5 | C21: =C5 -> 3046098.5 | E21: =E5 -> 3046098.5 | F21: =F5 -> 3046098.5
A22: Accumulated Depreciation | B22: =B13+B18 -> 140203.94 | C22: =C13+C18 -> 148296.81 | E22: =E13+E18 -> 151036.54 | F22: =F13+F18 -> 145557.09
A23: Accumulated Impairment | C23: =C15 -> 1714240 | E23: =E15 -> 1514240 | F23: =F15 -> 1914240
A24: Carrying Value | B24: =B21-B22-B23 -> 2905894.6 | C24: =C21-C22-C23 -> 1183561.7 | E24: =E21-E22-E23 -> 1380821.9 | F24: =F21-F22-F23 -> 986301.38
A26: RUL | B26: =B6-B11-B12 -> 3482 | C26: =C16-C12 -> 720 | E26: =E16-E12 -> 720 | F26: =F16-F12 -> 720
A28: Depreciation 2025 | B28: =ROUND((B24-B8)/B26*365,2) -> 304609.75 | C28: =ROUND((C24-C8)/C26*365,2) -> 599999.5 | E28: =ROUND((E24-E8)/E26*365,2) -> 699999.5 | F28: =ROUND((F24-F8)/F26*365,2) -> 499999.5
A32: Cost | B32: =B5 -> 3046098.5 | C32: =C5 -> 3046098.5 | E32: =E5 -> 3046098.5 | F32: =F5 -> 3046098.5
A33: Accumulated Depreciation | B33: =B22+B28 -> 444813.69 | C33: =C22+C28 -> 748296.31 | E33: =E22+E28 -> 851036.04 | F33: =F22+F28 -> 645556.59
A34: Accumulated Impairment | C34: =C23 -> 1714240 | E34: =E23 -> 1514240 | F34: =F23 -> 1914240
A35: Carrying Value | B35: =B32-B33-B34 -> 2601284.8 | C35: =C32-C33-C34 -> 583562.16 | E35: =E32-E33-E34 -> 680822.43 | F35: =F32-F33-F34 -> 486301.88
B37: =B26-365 -> 3117 | C37: =C26-365 -> 355 | E37: =E26-365 -> 355 | F37: =F26-365 -> 355

Sheet 7.1
B3: Before revaluation | C3: Revaluation 30 June 2023 | D3: Before Impairment | E3: Impaired to R3m on 20 June 2024
A5: Cost | B5: 14067804 | C5: 12164247
A6: Accumulated depreciation | B6: 9749246.1 | C6: 6020788.8
A7: Accumulated impairment losses
A8: Revaluation reserve | B8: 3835148.2 | C8: 5660048.6
A9: Carrying Value | B9: =B5-B6 -> 4318557.7 | C9: =C5-C6 -> 6143458.2
A11: EUL | C11: 10957.5
A12: RUL | C12: 5534
A13: RUL after impairment | C13: 2192
A14: Residual Value | C14: 1
A15: Depreciation start date | C15: 45108
A16: Impairment date | C16: 45463
C17: 45473
A18: Day is use 20 June 2024 | C18: =C16-C15+1 -> 356
A19: Days in use 20 June to 30 June | C19: =C17-C15+1-C18 -> 10
A20: Accumulated Depreciation 20 June 2024 | D20: =ROUND((C9-C14)/C12*C18,2) -> 395206.14 | E20: =ROUND((C9-C14)/C12*C18,2) -> 395206.14
A21: Depreciation offset 20 June 2024 | D21: =ROUND(C8/C12*C18,2) -> 364108.66 | E21: =ROUND(C8/C12*C18,2) -> 364108.66
A23: Impairment | E23: =-3000000+(C9-E20) -> 2748252
A25: Depreciation 21 June to 30 June | D25: =ROUND((C9-C14-D20)/C12*C19,2) -> 10387.15 | E25: =ROUND((C9-C14-E20-E23)/C13*C19,2) -> 13686.13
A26: Depreciation offset 21 June to 30 June | D26: =ROUND(C8/C12*C19,2) -> 10227.77 | E26: =ROUND((C8-E21-E23)/C13*C19,2) -> 11622.66
A29: Cost | D29: =C5 -> 12164247 | E29: =C5 -> 12164247
A30: Accumulated Depreciation | D30: =C6+D20+D25 -> 6426382.1 | E30: =C6+E20+E25 -> 6429681.1
A31: Accumulated Impairment | E31: =E23 -> 2748252
A32: Carrying Value | D32: =D29-D30-D31 -> 5737864.9 | E32: =E29-E30-E31 -> 2986313.9
A33: Revaluation Reserve | D33: =C8-D21-D26 -> 5285712.2 | E33: =C8-E21-E23-E26 -> 2536065.3
A35: RUL | D35: =C12-C18-C19 -> 5168 | E35: =C13-C19 -> 2182
A37: Depreciation 2025 | D37: =ROUND((D32-C14)/D35*365,2) -> 405247.74 | E37: =ROUND((E32-C14)/E35*365,2) -> 499543.63
A38: Depreciation offset 2025 | D38: =ROUND(D33/D35*365,2) -> 373313.65 | E38: =ROUND(E33/E35*365,2) -> 424227.23
A41: Cost | D41: =D29 -> 12164247 | E41: =C5 -> 12164247
A42: Accumulated Depreciation | D42: =D30+D37 -> 6831629.9 | E42: =E30+E37 -> 6929224.7
A43: Accumulated Impairment | E43: =E31 -> 2748252
A44: Carrying Value | D44: =D41-D42-D43 -> 5332617.1 | E44: =E41-E42-E43 -> 2486770.2
A45: Revaluation Reserve | D45: =D33-D38 -> 4912398.5 | E45: =E33-E38 -> 2111838
D47: =D35-365 -> 4803 | E47: =E35-365 -> 1817

Sheet 7.2
B3: Before revaluation | C3: Revaluation 30 June 2023 | D3: Impaired to R3m on 20 June 2024 | E3: Impaired to R2m on 20 June 2024
A5: Cost | B5: 14067804 | C5: 12164247
A6: Accumulated depreciation | B6: 9749246.1 | C6: 6020788.8
A7: Accumulated impairment losses
A8: Revaluation reserve | B8: 3835148.2 | C8: 5660048.6
A9: Carrying Value | B9: =B5-B6 -> 4318557.7 | C9: =C5-C6 -> 6143458.2
A11: Impaired to | D11: 3000000 | E11: 2000000
A12: EUL | C12: 10957.5
A13: RUL | C13: 5534
A14: RUL after impairment | C14: 2192
A15: Residual Value | C15: 1
A16: Depreciation start date | C16: 45108
A17: Impairment date | C17: 45463
C18: 45473
A19: Day is use 20 June 2024 | C19: =C17-C16+1 -> 356
A20: Days in use 20 June to 30 June | C20: =C18-C16+1-C19 -> 10
A21: Accumulated Depreciation 20 June 2024 | D21: =ROUND((C9-C15)/C13*C19,2) -> 395206.14 | E21: =ROUND((C9-C15)/C13*C19,2) -> 395206.14
A22: Depreciation offset 20 June 2024 | D22: =ROUND(C8/C13*C19,2) -> 364108.66 | E22: =ROUND(C8/C13*C19,2) -> 364108.66
A24: Impairment | D24: =-D11+(C9-D21) -> 2748252 | E24: =-E11+(C9-E21) -> 3748252
A26: Depreciation 21 June to 30 June | D26: =ROUND((C9-C15-D21-D24)/C14*C20,2) -> 13686.13 | E26: =ROUND((C9-C15-E21-E24)/C14*C20,2) -> 9124.08
A27: Depreciation offset 21 June to 30 June | D27: =ROUND((C8-D22-D24)/C14*C20,2) -> 11622.66 | E27: =ROUND((C8-E22-E24)/C14*C20,2) -> 7060.62
A30: Cost | D30: =C5 -> 12164247 | E30: =C5 -> 12164247
A31: Accumulated Depreciation | D31: =C6+D21+D26 -> 6429681.1 | E31: =C6+E21+E26 -> 6425119.1
A32: Accumulated Impairment | D32: =D24 -> 2748252 | E32: =E24 -> 3748252
A33: Carrying Value | D33: =D30-D31-D32 -> 2986313.9 | E33: =E30-E31-E32 -> 1990875.9
A34: Revaluation Reserve | D34: =C8-D22-D24-D27 -> 2536065.3 | E34: =C8-E22-E24-E27 -> 1540627.3
A36: RUL | D36: =C14-C20 -> 2182 | E36: =C14-C20 -> 2182
A38: Depreciation 2025 | D38: =ROUND((D33-C15)/D36*365,2) -> 499543.63 | E38: =ROUND((E33-C15)/E36*365,2) -> 333029.03
A39: Depreciation offset 2025 | D39: =ROUND(D34/D36*365,2) -> 424227.23 | E39: =ROUND(E34/E36*365,2) -> 257712.63
A42: Cost | D42: =C5 -> 12164247 | E42: =C5 -> 12164247
A43: Accumulated Depreciation | D43: =D31+D38 -> 6929224.7 | E43: =E31+E38 -> 6758148.1
A44: Accumulated Impairment | D44: =D32 -> 2748252 | E44: =E32 -> 3748252
A45: Carrying Value | D45: =D42-D43-D44 -> 2486770.2 | E45: =E42-E43-E44 -> 1657846.9
A46: Revaluation Reserve | D46: =D34-D39 -> 2111838 | E46: =E34-E39 -> 1282914.7
D48: =D36-365 -> 1817 | E48: =E36-365 -> 1817

Sheet 7.3
B3: Before revaluation | C3: Revaluation 30 June 2023 | D3: Impaired to R3m on 20 June 2024 | E3: Impaired to R4m on 20 June 2024
A5: Cost | B5: 14067804 | C5: 12164247
A6: Accumulated depreciation | B6: 9749246.1 | C6: 6020788.8
A7: Accumulated impairment losses
A8: Revaluation reserve | B8: 3835148.2 | C8: 5660048.6
A9: Carrying Value | B9: =B5-B6 -> 4318557.7 | C9: =C5-C6 -> 6143458.2
A11: Impaired to | D11: 3000000 | E11: 4000000
A12: EUL | C12: 10957.5
A13: RUL | C13: 5534
A14: RUL after impairment | C14: 2192
A15: Residual Value | C15: 1
A16: Depreciation start date | C16: 45108
A17: Impairment date | C17: 45463
C18: 45473
A19: Day is use 20 June 2024 | C19: =C17-C16+1 -> 356
A20: Days in use 20 June to 30 June | C20: =C18-C16+1-C19 -> 10
A21: Accumulated Depreciation 20 June 2024 | D21: =ROUND((C9-C15)/C13*C19,2) -> 395206.14 | E21: =ROUND((C9-C15)/C13*C19,2) -> 395206.14
A22: Depreciation offset 20 June 2024 | D22: =ROUND(C8/C13*C19,2) -> 364108.66 | E22: =ROUND(C8/C13*C19,2) -> 364108.66
A24: Impairment | D24: =-D11+(C9-D21) -> 2748252 | E24: =-E11+(C9-E21) -> 1748252
A26: Depreciation 21 June to 30 June | D26: =ROUND((C9-C15-D21-D24)/C14*C20,2) -> 13686.13 | E26: =ROUND((C9-C15-E21-E24)/C14*C20,2) -> 18248.17
A27: Depreciation offset 21 June to 30 June | D27: =ROUND((C8-D22-D24)/C14*C20,2) -> 11622.66 | E27: =ROUND((C8-E22-E24)/C14*C20,2) -> 16184.71
A30: Cost | D30: =C5 -> 12164247 | E30: =C5 -> 12164247
A31: Accumulated Depreciation | D31: =C6+D21+D26 -> 6429681.1 | E31: =C6+E21+E26 -> 6434243.1
A32: Accumulated Impairment | D32: =D24 -> 2748252 | E32: =E24 -> 1748252
A33: Carrying Value | D33: =D30-D31-D32 -> 2986313.9 | E33: =E30-E31-E32 -> 3981751.8
A34: Revaluation Reserve | D34: =C8-D22-D24-D27 -> 2536065.3 | E34: =C8-E22-E24-E27 -> 3531503.2
A36: RUL | D36: =C14-C20 -> 2182 | E36: =C14-C20 -> 2182
A38: Depreciation 2025 | D38: =ROUND((D33-C15)/D36*365,2) -> 499543.63 | E38: =ROUND((E33-C15)/E36*365,2) -> 666058.23
A39: Depreciation offset 2025 | D39: =ROUND(D34/D36*365,2) -> 424227.23 | E39: =ROUND(E34/E36*365,2) -> 590741.83
A42: Cost | D42: =C5 -> 12164247 | E42: =C5 -> 12164247
A43: Accumulated Depreciation | D43: =D31+D38 -> 6929224.7 | E43: =E31+E38 -> 7100301.4
A44: Accumulated Impairment | D44: =D32 -> 2748252 | E44: =E32 -> 1748252
A45: Carrying Value | D45: =D42-D43-D44 -> 2486770.2 | E45: =E42-E43-E44 -> 3315693.6
A46: Revaluation Reserve | D46: =D34-D39 -> 2111838 | E46: =E34-E39 -> 2940761.4
D48: =D36-365 -> 1817 | E48: =E36-365 -> 1817

Sheet 8
D2: 8.1 | E2: 8.2
B3: Normal without impairment | C3: Impaired to 1200000 | D3: Impairment reversed max | E3: Impairment reversed portion
A5: Cost | B5: 3046098.5 | C5: 3046098.5 | D5: 3046098.5 | E5: 3046098.5
A6: EUL | B6: 3650 | C6: 3650 | D6: 3650 | E6: 3650
A7: Acquisition date | B7: 44941 | C7: 44941 | D7: 44941 | E7: 44941
A8: Residual Value | B8: 1 | C8: 1 | D8: 1 | E8: 1
A9: Impairment date | B9: 45097 | C9: 45097 | D9: 45097 | E9: 45097
B10: 45107 | C10: 45107 | D10: 45107 | E10: 45107
A11: Day is use 20 June 2023 | B11: =B9-B7+1 -> 157 | C11: =C9-C7+1 -> 157 | D11: =D9-D7+1 -> 157 | E11: =E9-E7+1 -> 157
A12: Days in use 20 June to 30 June 2023 | B12: =B10-B7+1-B11 -> 10 | C12: =C10-C7+1-C11 -> 10 | D12: =D10-D7+1-D11 -> 10 | E12: =E10-E7+1-E11 -> 10
A13: Accumulated Depreciation 20 June 2023 | B13: =ROUND((B5-B8)/B6*B11,2) -> 131023.92 | C13: =ROUND((C5-C8)/C6*C11,2) -> 131023.92 | D13: =ROUND((D5-D8)/D6*D11,2) -> 131023.92 | E13: =ROUND((E5-E8)/E6*E11,2) -> 131023.92
A15: Impaired to R1200000 | C15: 1200000 | D15: 1200000 | E15: 1200000
A16: Impairment | C16: =C5-C13-C15 -> 1715074.6 | D16: =D5-D13-D15 -> 1715074.6 | E16: =E5-E13-E15 -> 1715074.6
A17: RUL after impairment | C17: 1460 | D17: 1460 | E17: 1460
A19: Depreciation 21 June to 30 June | B19: =ROUND((B5-B8)/B6*B12,2) -> 8345.47 | C19: =ROUND((C5-C13-C16-C8)/C17*C12,2) -> 8219.17 | D19: =ROUND((D5-D13-D16-D8)/D17*D12,2) -> 8219.17 | E19: =ROUND((E5-E13-E16-E8)/E17*E12,2) -> 8219.17
A21: 2023
A22: Cost | B22: =B5 -> 3046098.5 | C22: =C5 -> 3046098.5 | D22: =D5 -> 3046098.5 | E22: =E5 -> 3046098.5
A23: Accumulated Depreciation | B23: =B13+B19 -> 139369.39 | C23: =C13+C19 -> 139243.09 | D23: =D13+D19 -> 139243.09 | E23: =E13+E19 -> 139243.09
A24: Accumulated Impairment | C24: =C16 -> 1715074.6 | D24: =D16 -> 1715074.6 | E24: =E16 -> 1715074.6
A25: Carrying Value | B25: =B22-B23-B24 -> 2906729.1 | C25: =C22-C23-C24 -> 1191780.8 | D25: =D22-D23-D24 -> 1191780.8 | E25: =E22-E23-E24 -> 1191780.8
A27: RUL | B27: =B6-B11-B12 -> 3483 | C27: =C17-C12 -> 1450 | D27: =D17-D12 -> 1450 | E27: =E17-E12 -> 1450
A29: Impairment reversal on | B29: 45275 | C29: 45275 | D29: 45275 | E29: 45275
B30: 45473 | C30: 45473 | D30: 45473 | E30: 45473
A31: Days in use to impairment reversal | B31: =B29-B10 -> 168 | C31: =C29-C10 -> 168 | D31: =D29-D10 -> 168 | E31: =E29-E10 -> 168
A32: Days in use up to 30 June 2024 | B32: =B30-B29 -> 198 | C32: =C30-C29 -> 198 | D32: =D30-D29 -> 198 | E32: =E30-E29 -> 198
A34: Depreciation 2024 up to impairment reversal | B34: =ROUND((B25-B8)/B27*B31,2) -> 140203.94 | C34: =ROUND((C25-C8)/C27*C31,2) -> 138082.08 | D34: =ROUND((D25-D8)/D27*D31,2) -> 138082.08 | E34: =ROUND((E25-E8)/E27*E31,2) -> 138082.08
A35: Depreciation 2024 up to year end | B35: =ROUND((B25-B8)/B27*B32,2) -> 165240.36 | C35: =ROUND((C25-C8)/C27*C32,2) -> 162739.59 | D35: =ROUND((D25-D34+D36-D8)/D37*D32,2) -> 165240.36 | E35: =ROUND((E25-E34+E36-E8)/E37*E32,2) -> 165180.99
A36: Impairment reversal | B36: =B25-B34 -> 2766525.2 | D36: =B36-(D25-D34) -> 1712826.4 | E36: 800000
A37: RUL at inpairment reversal | B37: =B27-B31 -> 3315 | D37: =B37 -> 3315 | E37: 2222
A39: Cost | B39: =B5 -> 3046098.5 | C39: =C5 -> 3046098.5 | D39: =D5 -> 3046098.5 | E39: =E5 -> 3046098.5
A40: Accumulated Depreciation | B40: =B23+B34+B35 -> 444813.69 | C40: =C23+C34+C35 -> 440064.76 | D40: =D23+D34+D35 -> 442565.53 | E40: =E23+E34+E35 -> 442506.16
A41: Accumulated Impairment | C41: =C24 -> 1715074.6 | D41: =D24-D36 -> 2248.16 | E41: =E24-E36 -> 915074.59
A42: Carrying Value | B42: =B39-B40-B41 -> 2601284.8 | C42: =C39-C40-C41 -> 890959.16 | D42: =D39-D40-D41 -> 2601284.8 | E42: =E39-E40-E41 -> 1688517.8
B44: =B27-B31-B32 -> 3117 | C44: =C27-C31-C32 -> 1084 | D44: =D37-D32 -> 3117 | E44: =E37-E32 -> 2024
A46: Depreciation 2025 | B46: =ROUND(B42/B44*365,2) -> 304609.87 | C46: =ROUND(C42/C44*365,2) -> 300000.09 | D46: =ROUND(D42/D44*365,2) -> 304609.87 | E46: =ROUND(E42/E44*365,2) -> 304500.49
A48: Cost | B48: =B22 -> 3046098.5 | C48: =C22 -> 3046098.5 | D48: =D22 -> 3046098.5 | E48: =E22 -> 3046098.5
A49: Accumulated Depreciation | B49: =B40+B46 -> 749423.56 | C49: =C40+C46 -> 740064.85 | D49: =D40+D46 -> 747175.4 | E49: =E40+E46 -> 747006.65
A50: Accumulated Impairment | C50: =C41 -> 1715074.6 | D50: =D41 -> 2248.16 | E50: =E41 -> 915074.59
A51: Carrying Value | B51: =B48-B49-B50 -> 2296674.9 | C51: =C48-C49-C50 -> 590959.07 | D51: =D48-D49-D50 -> 2296674.9 | E51: =E48-E49-E50 -> 1384017.3
B53: =B44-365 -> 2752 | C53: =C44-365 -> 719 | D53: =D44-365 -> 2752 | E53: =E44-365 -> 1659

Sheet 9
E2: 9.1 | F2: 9.2
B3: Before revaluation | C3: Revaluation 30 June 2022 No impairment | D3: Impaired to R3m on 20 June 2024 | E3: Impaired to R3m on 20 June 2024 Max reversal | F3: Impaired to R3m on 20 June 2024 Partial reversal | H3: 9.1 Asset revalues on 30 June 2022, sunsequently impaired to R3m on 2023/06/20. On 2024/06/20 the impairment was reversed
A5: Cost | B5: 14067804 | C5: 12164247 | D5: 12164247 | E5: 12164247 | F5: 12164247
A6: Accumulated depreciation | B6: 9749246.1 | C6: 6020788.8 | D6: 6020788.8 | E6: 6020788.8 | F6: 6020788.8
A7: Accumulated impairment losses
A8: Revaluation reserve | B8: 3835148.2 | C8: 5660048.6 | D8: 5660048.6 | E8: 5660048.6 | F8: 5660048.6
A9: Carrying Value | B9: =B5-B6 -> 4318557.7 | C9: =C5-C6 -> 6143458.2 | D9: =D5-D6 -> 6143458.2 | E9: =E5-E6 -> 6143458.2 | F9: =F5-F6 -> 6143458.2
A11: EUL | C11: 10957.5 | D11: 10957.5 | E11: 10957.5 | F11: 10957.5
A12: RUL | C12: 5534 | D12: 5534 | E12: 5534 | F12: 5534
A13: RUL after impairment | C13: 2800 | D13: 2800 | E13: 2800 | F13: 2800
A14: Residual Value | C14: 1 | D14: 1 | E14: 1 | F14: 1
A15: Depreciation start date | C15: 44743 | D15: 44743 | E15: 44743 | F15: 44743
A16: Impairment date | C16: 45097 | D16: 45097 | E16: 45097 | F16: 45097
C17: 45107 | D17: 45107 | E17: 45107 | F17: 45107
A18: Day is use 20 June 2023 | C18: =C16-C15+1 -> 355 | D18: =D16-D15+1 -> 355 | E18: =E16-E15+1 -> 355 | F18: =F16-F15+1 -> 355
A19: Days in use 20 June to 30 June 2023 | C19: =C17-C15+1-C18 -> 10 | D19: =D17-D15+1-D18 -> 10 | E19: =E17-E15+1-E18 -> 10 | F19: =F17-F15+1-F18 -> 10
A20: Accumulated Depreciation 20 June 2023 | C20: =ROUND((C9-C14)/C12*C18,2) -> 394096.01 | D20: =ROUND((D9-D14)/D12*D18,2) -> 394096.01 | E20: =ROUND((E9-E14)/E12*E18,2) -> 394096.01 | F20: =ROUND((F9-F14)/F12*F18,2) -> 394096.01
A21: Depreciation offset 20 June 2023 | C21: =ROUND(C8/C12*C18,2) -> 363085.88 | D21: =ROUND(D8/D12*D18,2) -> 363085.88 | E21: =ROUND(E8/E12*E18,2) -> 363085.88 | F21: =ROUND(F8/F12*F18,2) -> 363085.88
A23: Impaired to | D23: 3000000 | E23: 3000000 | F23: 3000000
A24: Impairment | D24: =-D23+(D9-D20) -> 2749362.2 | E24: =-E23+(E9-E20) -> 2749362.2 | F24: =-F23+(F9-F20) -> 2749362.2
A26: Depreciation 21 June to 30 June 2023 | C26: =ROUND((C9-C14)/(C12)*C19,2) -> 11101.3 | D26: =ROUND((D9-D14-D20-D24)/(D13)*D19,2) -> 10714.28 | E26: =ROUND((E9-E14-E20-E24)/(E13)*E19,2) -> 10714.28 | F26: =ROUND((F9-F14-F20-F24)/(F13)*F19,2) -> 10714.28
A27: Depreciation offset 21 June to 30 June 2023 | C27: =ROUND(C8/C12*C19,2) -> 10227.77 | D27: =ROUND((D8-D21-D24)/D13*D19,2) -> 9098.57 | E27: =ROUND((E8-E21-E24)/E13*E19,2) -> 9098.57 | F27: =ROUND((F8-F21-F24)/F13*F19,2) -> 9098.57
A30: Cost | C30: =C5 -> 12164247 | D30: =D5 -> 12164247 | E30: =E5 -> 12164247 | F30: =F5 -> 12164247
A31: Accumulated Depreciation | C31: =C6+C20+C26 -> 6425986.1 | D31: =D6+D20+D26 -> 6425599.1 | E31: =E6+E20+E26 -> 6425599.1 | F31: =F6+F20+F26 -> 6425599.1
A32: Accumulated Impairment | D32: =D24 -> 2749362.2 | E32: =E24 -> 2749362.2 | F32: =F24 -> 2749362.2
A33: Carrying Value | C33: =C30-C31-C32 -> 5738260.9 | D33: =D30-D31-D32 -> 2989285.7 | E33: =E30-E31-E32 -> 2989285.7 | F33: =F30-F31-F32 -> 2989285.7
A34: Revaluation Reserve | C34: =C8-C21-C27 -> 5286735 | D34: =D8-D21-D27-D24 -> 2538502 | E34: =E8-E21-E27-E24 -> 2538502 | F34: =F8-F21-F27-F24 -> 2538502
A36: RUL | C36: =C12-C18-C19 -> 5169 | D36: =D13-D19 -> 2790 | E36: =E13-E19 -> 2790 | F36: =F13-F19 -> 2790
A38: Impairment reversal on | C38: 45275 | D38: 45275 | E38: 45275 | F38: 45275
C39: 45473 | D39: 45473 | E39: 45473 | F39: 45473
A40: Days in use to impairment reversal | C40: =C38-C17 -> 168 | D40: =D38-D17 -> 168 | E40: =E38-E17 -> 168 | F40: =F38-F17 -> 168
A41: Days in use up to 30 June 2024 | C41: =C39-C38 -> 198 | D41: =D39-D38 -> 198 | E41: =E39-E38 -> 198 | F41: =F39-F38 -> 198
A44: Depreciation 2024 up to impairment reversal date | C44: =ROUND((C33-C14)/C36*C40,2) -> 186501.77 | D44: =ROUND((D33-D14)/D36*D40,2) -> 179999.94 | E44: =ROUND((E33-E14)/E36*E40,2) -> 179999.94 | F44: =ROUND((F33-F14)/F36*F40,2) -> 179999.94
A45: Depreciation offset 2024 up to impairment reversal date | C45: =ROUND(C34/C36*C40,2) -> 171826.56 | D45: =ROUND((D34)/D36*D40,2) -> 152856.03 | E45: =ROUND((E34)/E36*E40,2) -> 152856.03 | F45: =ROUND((F34)/F36*F40,2) -> 152856.03
A47: Depreciation 2024 up toyear end | C47: =ROUND((C33-C14)/C36*C41,2) -> 219805.66 | D47: =ROUND((D33-D14)/D36*D41,2) -> 212142.79 | E47: =ROUND((E33-E14-E44+E50)/E51*E41,2) -> 219805.66 | F47: =ROUND((F33-F14-F44+F50)/F51*F41,2) -> 228840.85
A48: Depreciation offset 2024 up to year end | C48: =ROUND(C34/C36*C41,2) -> 202509.87 | D48: =ROUND((D34)/D36*D41,2) -> 180151.75 | E48: =ROUND((E34-E45+E50)/E51*E41,2) -> 203032.92 | F48: =ROUND((F34-F45+F50)/F51*F41,2) -> 205809.42
A50: Impairment reversal | C50: =C33-C44 -> 5551759.1 | E50: =C50-E33+E44 -> 2742473.3 | F50: 1400000
A51: RUL at inpairment reversal | C51: =C36-C40 -> 5001 | E51: 5001 | F51: 3642
A54: Cost | C54: =C30 -> 12164247 | D54: =D30 -> 12164247 | E54: =E30 -> 12164247 | F54: =F30 -> 12164247
A55: Accumulated Depreciation | C55: =C31+C44+C47 -> 6832293.6 | D55: =D31+D44+D47 -> 6817741.9 | E55: =E31+E44+E47 -> 6825404.7 | F55: =F31+F44+F47 -> 6834439.9
...

Sheet 10.1
B3: Normal | C3: Disposed
A5: Cost | B5: 3046098.5 | C5: 3046098.5
A6: EUL | B6: 3650 | C6: 3650
A7: Acquisition date | B7: 45306 | C7: 45306
A8: Residual Value | B8: 1 | C8: 1
A9: Disposal date | B9: 45463 | C9: 45463
B10: 45473 | C10: 45473
A11: Day is use 20 June 2024 | B11: =B9-B7+1 -> 158 | C11: =C9-C7+1 -> 158
A12: Days in use 20 June to 30 June | B12: =B10-B7+1-B11 -> 10 | C12: =C10-C7+1-C11 -> 10
A13: Accumulated Depreciation 20 June 2024 | B13: =ROUND((B5-B8)/B6*B11,2) -> 131858.47 | C13: =ROUND((C5-C8)/C6*C11,2) -> 131858.47
A15: Disposal cost | C15: =-C5 -> -3046098.5
A16: Disposal accumulated depreciation | C16: =-C13 -> -131858.47
A18: Depreciation 21 June to 30 June | B18: =ROUND((B5-B8)/B6*B12,2) -> 8345.47
A21: Cost | B21: =B5 -> 3046098.5 | C21: =+C5+C15 -> 0
A22: Accumulated Depreciation | B22: =B13+B18 -> 140203.94 | C22: =C13+C16 -> 0
A23: Accumulated Impairment
A24: Carrying Value | B24: =B21-B22-B23 -> 2905894.6 | C24: =C21-C22-C23 -> 0
A26: RUL | B26: =B6-B11-B12 -> 3482
A28: Depreciation 2025 | B28: =ROUND((B24-B8)/B26*365,2) -> 304609.75
A32: Cost | B32: =B5 -> 3046098.5
A33: Accumulated Depreciation | B33: =B22+B28 -> 444813.69
A34: Accumulated Impairment
A35: Carrying Value | B35: =B32-B33-B34 -> 2601284.8 | C35: =C32-C33-C34 -> 0
B37: =B26-365 -> 3117 | C37: 0

Sheet 10.2
B3: Normal | C3: Impaired | E3: Disposed
A5: Cost | B5: 3046098.5 | C5: 3046098.5 | E5: 3046098.5
A6: EUL | B6: 3650 | C6: 3650 | E6: 3650
A7: Acquisition date | B7: 45306 | C7: 45306 | E7: 45306
A8: Residual Value | B8: 1 | C8: 1 | E8: 1
A9: Impairment date | B9: 45463 | C9: 45463 | E9: 45463
B10: 45473 | C10: 45473 | E10: 45473
A11: Day is use 20 June 2024 | B11: =B9-B7+1 -> 158 | C11: =C9-C7+1 -> 158 | E11: =E9-E7+1 -> 158
A12: Days in use 20 June to 30 June | B12: =B10-B7+1-B11 -> 10 | C12: =C10-C7+1-C11 -> 10 | E12: =E10-E7+1-E11 -> 10
A13: Disposal date | E13: 45468
A14: Days in use 20 June to 25 June | E14: =E13-E9+1 -> 6
A16: Accumulated Depreciation 20 June 2024 | B16: =ROUND((B5-B8)/B6*B11,2) -> 131858.47 | C16: =ROUND((C5-C8)/C6*C11,2) -> 131858.47 | E16: =ROUND((E5-E8)/E6*E11,2) -> 131858.47
A18: Impairment | C18: =C5-C16-1200000 -> 1714240 | E18: =E5-E16-1200000 -> 1714240
A19: RUL after impairment | C19: 730 | E19: 730
A21: Depreciation 21 June to 30 June/ Disposal date | B21: =ROUND((B5-B8)/B6*B12,2) -> 8345.47 | C21: =ROUND((C5-C16-C18-C8)/C19*C12,2) -> 16438.34 | E21: =ROUND((E5-E16-E18-E8)/E19*E14,2) -> 9863.01
A23: Disposal - Cost | E23: =-E5 -> -3046098.5
A24: Disposal - Accumulated Depreciation | E24: =-E16-E21 -> -141721.48
A25: Disposal - Accumulated Impairment | E25: =-E18 -> -1714240
A28: Cost | B28: =B5 -> 3046098.5 | C28: =C5 -> 3046098.5 | E28: =E5+E23 -> 0
A29: Accumulated Depreciation | B29: =B16+B21 -> 140203.94 | C29: =C16+C21 -> 148296.81 | E29: =E16+E21+E24 -> 0
A30: Accumulated Impairment | C30: =C18 -> 1714240 | E30: =E18+E25 -> 0
A31: Carrying Value | B31: =B28-B29-B30 -> 2905894.6 | C31: =C28-C29-C30 -> 1183561.7 | E31: =E28-E29-E30 -> 0
A33: RUL | B33: =B6-B11-B12 -> 3482 | C33: =C19-C12 -> 720
A35: Depreciation 2025 | B35: =ROUND((B31-B8)/B33*365,2) -> 304609.75 | C35: =ROUND((C31-C8)/C33*365,2) -> 599999.5
A39: Cost | B39: =B5 -> 3046098.5 | C39: =C5 -> 3046098.5
A40: Accumulated Depreciation | B40: =B29+B35 -> 444813.69 | C40: =C29+C35 -> 748296.31
A41: Accumulated Impairment | C41: =C30 -> 1714240
A42: Carrying Value | B42: =B39-B40-B41 -> 2601284.8 | C42: =C39-C40-C41 -> 583562.16 | E42: =E39-E40-E41 -> 0
B44: =B33-365 -> 3117 | C44: =C33-365 -> 355

Sheet 11.1
E2: 6.1
B3: Before revaluation | C3: Revaluation 30 June 2023 | D3: Normal | E3: Disposed
A5: Cost | B5: 14067804 | C5: 12164247
A6: Accumulated depreciation | B6: 9749246.1 | C6: 6020788.8
A7: Accumulated impairment losses
A8: Revaluation reserve | B8: 3835148.2 | C8: 5660048.6 | G8: =C8 -> 5660048.6 | H8: =C8 -> 5660048.6
A9: Carrying Value | B9: =B5-B6 -> 4318557.7 | C9: =C5-C6 -> 6143458.2
A11: EUL | C11: 10957.5
A12: RUL | C12: 5534
